#VRML_SIM R2023a utf8

EXTERNPROTO "https://raw.githubusercontent.com/cyberbotics/webots/R2023a/projects/objects/backgrounds/protos/TexturedBackground.proto"
EXTERNPROTO "https://raw.githubusercontent.com/cyberbotics/webots/R2023a/projects/objects/backgrounds/protos/TexturedBackgroundLight.proto"
EXTERNPROTO "https://raw.githubusercontent.com/cyberbotics/webots/R2023a/projects/objects/floors/protos/Floor.proto"

WorldInfo {
  basicTimeStep 16
}
Viewpoint {
  orientation -0.392687598297836 0.35844021624126055 0.8469457252528028 1.8253794801919647
  position 0.8079824137838252 -5.229003714764903 6.016514490488832
}
TexturedBackground {
}
TexturedBackgroundLight {
}
Floor {
  size 3 3
}
Robot {
  translation -0.30846 1.21065 0.04
  rotation -3.1121999999660073e-06 3.486979999961914e-06 0.9999999999890776 -3.1154253071795863
  children [
    DistanceSensor {
      translation 0.1 0.04 0
      rotation 0 0 1 0.5235996938995747
      children [
        DEF sensor_shape Shape {
          appearance PBRAppearance {
            metalness 0
          }
          geometry Box {
            size 0.01 0.01 0.01
          }
        }
      ]
      name "ds_left"
      boundingObject USE sensor_shape
      physics Physics {
      }
      lookupTable [
        0 0 0
        0.3 30 0
      ]
    }
    DistanceSensor {
      translation 0.1 0 0
      children [
        Shape {
          appearance PBRAppearance {
            metalness 0
          }
          geometry Box {
            size 0.01 0.01 0.01
          }
        }
      ]
      name "ds_center"
      boundingObject USE sensor_shape
      physics Physics {
      }
      lookupTable [
        0 0 0
        0.29 30 0
      ]
    }
    DistanceSensor {
      translation 0.1 -0.04 0
      rotation 0 0 1 -0.5235996938995747
      children [
        Shape {
          appearance PBRAppearance {
            metalness 0
          }
          geometry Box {
            size 0.01 0.01 0.01
          }
        }
      ]
      name "ds_right"
      boundingObject USE sensor_shape
      physics Physics {
      }
      lookupTable [
        0 0 0
        0.3 30 0
      ]
    }
    Compass {
    }
    GPS {
    }
    HingeJoint {
      jointParameters HingeJointParameters {
        position 2.2047993463578495
        axis 0 1 0
        anchor 0.05 0.06 0
      }
      device [
        RotationalMotor {
          name "wheel1"
        }
      ]
      endPoint DEF Wheel1 Solid {
        translation 0.04999987479910899 0.06 -2.8030859540570134e-07
        rotation 0.33687947315228084 0.665773495430891 -0.6657761435725789 2.4917177063177345
        children [
          DEF Wheel Shape {
            appearance PBRAppearance {
              baseColor 0 1 0
              metalness 0
            }
            geometry Cylinder {
              height 0.02
              radius 0.04
            }
          }
        ]
        name "solid wheel1"
        boundingObject USE Wheel
        physics DEF Wheel_PH Physics {
        }
      }
    }
    HingeJoint {
      jointParameters HingeJointParameters {
        position 2.366400091499618
        axis 0 1 0
        anchor 0.05 -0.06 0
      }
      device [
        RotationalMotor {
          name "wheel2"
        }
      ]
      endPoint DEF Wheel2 Solid {
        translation 0.049998427923253014 -0.059999999566905826 1.174061164659025e-06
        rotation -0.2773762279067109 -0.6793597427564605 0.6793620302269772 3.6827389714547
        children [
          USE Wheel
        ]
        name "wheel2"
        boundingObject USE Wheel
        physics USE Wheel_PH
      }
    }
    HingeJoint {
      jointParameters HingeJointParameters {
        position 2.204799059788959
        axis 0 1 0
        anchor -0.05 0.06 0
      }
      device [
        RotationalMotor {
          name "wheel3"
        }
      ]
      endPoint DEF Wheel3 Solid {
        translation -0.050001740802103664 0.05999999956724689 9.04793725832726e-07
        rotation -0.3368794852963824 -0.6657736955576118 0.665775937301736 3.791467993444681
        children [
          USE Wheel
        ]
        name "wheel3"
        boundingObject USE Wheel
        physics USE Wheel_PH
      }
    }
    HingeJoint {
      jointParameters HingeJointParameters {
        position 2.3663998179324777
        axis 0 1 0
        anchor -0.05 -0.06 0
      }
      device [
        RotationalMotor {
          name "wheel4"
        }
      ]
      endPoint DEF Wheel4 Solid {
        translation -0.0500015720854401 -0.06000000043275322 1.1740495300853614e-06
        rotation -0.27737632677472557 -0.6793597225615942 0.6793620100550181 3.6827391550425483
        children [
          USE Wheel
        ]
        name "wheel4"
        boundingObject USE Wheel
        physics USE Wheel_PH
      }
    }
    DEF BODY Shape {
      appearance PBRAppearance {
        baseColor 0 0 1
        metalness 0
        IBLStrength 0
        normalMapFactor 0
        occlusionMapStrength 0
      }
      geometry Box {
        size 0.2 0.1 0.05
      }
    }
  ]
  name "robot_8"
  boundingObject USE BODY
  physics Physics {
  }
  controller "rpyc_robot"
}
Robot {
  translation -0.0726688 0.543174 0.04
  rotation -2.2137199999757878e-06 4.120009999954938e-06 0.9999999999890625 -3.063055307179586
  children [
    DistanceSensor {
      translation 0.1 0.04 0
      rotation 0 0 1 0.5235996938995747
      children [
        DEF sensor_shape Shape {
          appearance PBRAppearance {
            metalness 0
          }
          geometry Box {
            size 0.01 0.01 0.01
          }
        }
      ]
      name "ds_left"
      boundingObject USE sensor_shape
      physics Physics {
      }
      lookupTable [
        0 0 0
        0.3 30 0
      ]
    }
    DistanceSensor {
      translation 0.1 0 0
      children [
        Shape {
          appearance PBRAppearance {
            metalness 0
          }
          geometry Box {
            size 0.01 0.01 0.01
          }
        }
      ]
      name "ds_center"
      boundingObject USE sensor_shape
      physics Physics {
      }
      lookupTable [
        0 0 0
        0.29 30 0
      ]
    }
    DistanceSensor {
      translation 0.1 -0.04 0
      rotation 0 0 1 -0.5235996938995747
      children [
        Shape {
          appearance PBRAppearance {
            metalness 0
          }
          geometry Box {
            size 0.01 0.01 0.01
          }
        }
      ]
      name "ds_right"
      boundingObject USE sensor_shape
      physics Physics {
      }
      lookupTable [
        0 0 0
        0.3 30 0
      ]
    }
    Compass {
    }
    GPS {
    }
    HingeJoint {
      jointParameters HingeJointParameters {
        position 2.2047993463578495
        axis 0 1 0
        anchor 0.05 0.06 0
      }
      device [
        RotationalMotor {
          name "wheel1"
        }
      ]
      endPoint DEF Wheel1 Solid {
        translation 0.04999987479910899 0.06 -2.8030859540570134e-07
        rotation 0.33687947315228084 0.665773495430891 -0.6657761435725789 2.4917177063177345
        children [
          DEF Wheel Shape {
            appearance PBRAppearance {
              baseColor 0 1 0
              metalness 0
            }
            geometry Cylinder {
              height 0.02
              radius 0.04
            }
          }
        ]
        name "solid wheel1"
        boundingObject USE Wheel
        physics DEF Wheel_PH Physics {
        }
      }
    }
    HingeJoint {
      jointParameters HingeJointParameters {
        position 2.366400091499618
        axis 0 1 0
        anchor 0.05 -0.06 0
      }
      device [
        RotationalMotor {
          name "wheel2"
        }
      ]
      endPoint DEF Wheel2 Solid {
        translation 0.049998427923253014 -0.059999999566905826 1.174061164659025e-06
        rotation -0.2773762279067109 -0.6793597427564605 0.6793620302269772 3.6827389714547
        children [
          USE Wheel
        ]
        name "wheel2"
        boundingObject USE Wheel
        physics USE Wheel_PH
      }
    }
    HingeJoint {
      jointParameters HingeJointParameters {
        position 2.204799059788959
        axis 0 1 0
        anchor -0.05 0.06 0
      }
      device [
        RotationalMotor {
          name "wheel3"
        }
      ]
      endPoint DEF Wheel3 Solid {
        translation -0.050001740802103664 0.05999999956724689 9.04793725832726e-07
        rotation -0.3368794852963824 -0.6657736955576118 0.665775937301736 3.791467993444681
        children [
          USE Wheel
        ]
        name "wheel3"
        boundingObject USE Wheel
        physics USE Wheel_PH
      }
    }
    HingeJoint {
      jointParameters HingeJointParameters {
        position 2.3663998179324777
        axis 0 1 0
        anchor -0.05 -0.06 0
      }
      device [
        RotationalMotor {
          name "wheel4"
        }
      ]
      endPoint DEF Wheel4 Solid {
        translation -0.0500015720854401 -0.06000000043275322 1.1740495300853614e-06
        rotation -0.27737632677472557 -0.6793597225615942 0.6793620100550181 3.6827391550425483
        children [
          USE Wheel
        ]
        name "wheel4"
        boundingObject USE Wheel
        physics USE Wheel_PH
      }
    }
    DEF BODY Shape {
      appearance PBRAppearance {
        baseColor 1 0 0
        metalness 0
        IBLStrength 0
        normalMapFactor 0
        occlusionMapStrength 0
      }
      geometry Box {
        size 0.2 0.1 0.05
      }
    }
  ]
  name "robot_7"
  boundingObject USE BODY
  physics Physics {
  }
  controller "rpyc_robot"
}
Robot {
  translation 0.500277 1.10973 0.04
  rotation 1.45577999981534e-05 6.462419999180267e-06 -0.9999999998731539 0.595599
  children [
    DistanceSensor {
      translation 0.1 0.04 0
      rotation 0 0 1 0.5235996938995747
      children [
        DEF sensor_shape Shape {
          appearance PBRAppearance {
            metalness 0
          }
          geometry Box {
            size 0.01 0.01 0.01
          }
        }
      ]
      name "ds_left"
      boundingObject USE sensor_shape
      physics Physics {
      }
      lookupTable [
        0 0 0
        0.3 30 0
      ]
    }
    DistanceSensor {
      translation 0.1 0 0
      children [
        Shape {
          appearance PBRAppearance {
            metalness 0
          }
          geometry Box {
            size 0.01 0.01 0.01
          }
        }
      ]
      name "ds_center"
      boundingObject USE sensor_shape
      physics Physics {
      }
      lookupTable [
        0 0 0
        0.29 30 0
      ]
    }
    DistanceSensor {
      translation 0.1 -0.04 0
      rotation 0 0 1 -0.5235996938995747
      children [
        Shape {
          appearance PBRAppearance {
            metalness 0
          }
          geometry Box {
            size 0.01 0.01 0.01
          }
        }
      ]
      name "ds_right"
      boundingObject USE sensor_shape
      physics Physics {
      }
      lookupTable [
        0 0 0
        0.3 30 0
      ]
    }
    Compass {
    }
    GPS {
    }
    HingeJoint {
      jointParameters HingeJointParameters {
        position 2.2047993463578495
        axis 0 1 0
        anchor 0.05 0.06 0
      }
      device [
        RotationalMotor {
          name "wheel1"
        }
      ]
      endPoint DEF Wheel1 Solid {
        translation 0.04999987479910899 0.06 -2.8030859540570134e-07
        rotation 0.33687947315228084 0.665773495430891 -0.6657761435725789 2.4917177063177345
        children [
          DEF Wheel Shape {
            appearance PBRAppearance {
              baseColor 0 1 0
              metalness 0
            }
            geometry Cylinder {
              height 0.02
              radius 0.04
            }
          }
        ]
        name "solid wheel1"
        boundingObject USE Wheel
        physics DEF Wheel_PH Physics {
        }
      }
    }
    HingeJoint {
      jointParameters HingeJointParameters {
        position 2.366400091499618
        axis 0 1 0
        anchor 0.05 -0.06 0
      }
      device [
        RotationalMotor {
          name "wheel2"
        }
      ]
      endPoint DEF Wheel2 Solid {
        translation 0.049998427923253014 -0.059999999566905826 1.174061164659025e-06
        rotation -0.2773762279067109 -0.6793597427564605 0.6793620302269772 3.6827389714547
        children [
          USE Wheel
        ]
        name "wheel2"
        boundingObject USE Wheel
        physics USE Wheel_PH
      }
    }
    HingeJoint {
      jointParameters HingeJointParameters {
        position 2.204799059788959
        axis 0 1 0
        anchor -0.05 0.06 0
      }
      device [
        RotationalMotor {
          name "wheel3"
        }
      ]
      endPoint DEF Wheel3 Solid {
        translation -0.050001740802103664 0.05999999956724689 9.04793725832726e-07
        rotation -0.3368794852963824 -0.6657736955576118 0.665775937301736 3.791467993444681
        children [
          USE Wheel
        ]
        name "wheel3"
        boundingObject USE Wheel
        physics USE Wheel_PH
      }
    }
    HingeJoint {
      jointParameters HingeJointParameters {
        position 2.3663998179324777
        axis 0 1 0
        anchor -0.05 -0.06 0
      }
      device [
        RotationalMotor {
          name "wheel4"
        }
      ]
      endPoint DEF Wheel4 Solid {
        translation -0.0500015720854401 -0.06000000043275322 1.1740495300853614e-06
        rotation -0.27737632677472557 -0.6793597225615942 0.6793620100550181 3.6827391550425483
        children [
          USE Wheel
        ]
        name "wheel4"
        boundingObject USE Wheel
        physics USE Wheel_PH
      }
    }
    DEF BODY Shape {
      appearance PBRAppearance {
        baseColor 1 0 0
        metalness 0
        IBLStrength 0
        normalMapFactor 0
        occlusionMapStrength 0
      }
      geometry Box {
        size 0.2 0.1 0.05
      }
    }
  ]
  name "robot_6"
  boundingObject USE BODY
  physics Physics {
  }
  controller "rpyc_robot"
}
Robot {
  translation 0.400278 -0.58406 0.04
  rotation 4.380729999904942e-07 6.573149999857369e-06 0.9999999999783009 1.57735
  children [
    DistanceSensor {
      translation 0.1 0.04 0
      rotation 0 0 1 0.5235996938995747
      children [
        DEF sensor_shape Shape {
          appearance PBRAppearance {
            metalness 0
          }
          geometry Box {
            size 0.01 0.01 0.01
          }
        }
      ]
      name "ds_left"
      boundingObject USE sensor_shape
      physics Physics {
      }
      lookupTable [
        0 0 0
        0.3 30 0
      ]
    }
    DistanceSensor {
      translation 0.1 0 0
      children [
        Shape {
          appearance PBRAppearance {
            metalness 0
          }
          geometry Box {
            size 0.01 0.01 0.01
          }
        }
      ]
      name "ds_center"
      boundingObject USE sensor_shape
      physics Physics {
      }
      lookupTable [
        0 0 0
        0.29 30 0
      ]
    }
    DistanceSensor {
      translation 0.1 -0.04 0
      rotation 0 0 1 -0.5235996938995747
      children [
        Shape {
          appearance PBRAppearance {
            metalness 0
          }
          geometry Box {
            size 0.01 0.01 0.01
          }
        }
      ]
      name "ds_right"
      boundingObject USE sensor_shape
      physics Physics {
      }
      lookupTable [
        0 0 0
        0.3 30 0
      ]
    }
    Compass {
    }
    GPS {
    }
    HingeJoint {
      jointParameters HingeJointParameters {
        position 2.2047993463578495
        axis 0 1 0
        anchor 0.05 0.06 0
      }
      device [
        RotationalMotor {
          name "wheel1"
        }
      ]
      endPoint DEF Wheel1 Solid {
        translation 0.04999987479910899 0.06 -2.8030859540570134e-07
        rotation 0.33687947315228084 0.665773495430891 -0.6657761435725789 2.4917177063177345
        children [
          DEF Wheel Shape {
            appearance PBRAppearance {
              baseColor 0 1 0
              metalness 0
            }
            geometry Cylinder {
              height 0.02
              radius 0.04
            }
          }
        ]
        name "solid wheel1"
        boundingObject USE Wheel
        physics DEF Wheel_PH Physics {
        }
      }
    }
    HingeJoint {
      jointParameters HingeJointParameters {
        position 2.366400091499618
        axis 0 1 0
        anchor 0.05 -0.06 0
      }
      device [
        RotationalMotor {
          name "wheel2"
        }
      ]
      endPoint DEF Wheel2 Solid {
        translation 0.049998427923253014 -0.059999999566905826 1.174061164659025e-06
        rotation -0.2773762279067109 -0.6793597427564605 0.6793620302269772 3.6827389714547
        children [
          USE Wheel
        ]
        name "wheel2"
        boundingObject USE Wheel
        physics USE Wheel_PH
      }
    }
    HingeJoint {
      jointParameters HingeJointParameters {
        position 2.204799059788959
        axis 0 1 0
        anchor -0.05 0.06 0
      }
      device [
        RotationalMotor {
          name "wheel3"
        }
      ]
      endPoint DEF Wheel3 Solid {
        translation -0.050001740802103664 0.05999999956724689 9.04793725832726e-07
        rotation -0.3368794852963824 -0.6657736955576118 0.665775937301736 3.791467993444681
        children [
          USE Wheel
        ]
        name "wheel3"
        boundingObject USE Wheel
        physics USE Wheel_PH
      }
    }
    HingeJoint {
      jointParameters HingeJointParameters {
        position 2.3663998179324777
        axis 0 1 0
        anchor -0.05 -0.06 0
      }
      device [
        RotationalMotor {
          name "wheel4"
        }
      ]
      endPoint DEF Wheel4 Solid {
        translation -0.0500015720854401 -0.06000000043275322 1.1740495300853614e-06
        rotation -0.27737632677472557 -0.6793597225615942 0.6793620100550181 3.6827391550425483
        children [
          USE Wheel
        ]
        name "wheel4"
        boundingObject USE Wheel
        physics USE Wheel_PH
      }
    }
    DEF BODY Shape {
      appearance PBRAppearance {
        baseColor 1 0 0
        metalness 0
        IBLStrength 0
        normalMapFactor 0
        occlusionMapStrength 0
      }
      geometry Box {
        size 0.2 0.1 0.05
      }
    }
  ]
  name "robot_4"
  boundingObject USE BODY
  physics Physics {
  }
  controller "rpyc_robot"
}
Robot {
  translation 1.0415 0.132365 0.04
  rotation -4.1419099999292e-07 5.832309999900304e-06 0.9999999999829063 1.85223
  children [
    DistanceSensor {
      translation 0.1 0.04 0
      rotation 0 0 1 0.5235996938995747
      children [
        DEF sensor_shape Shape {
          appearance PBRAppearance {
            metalness 0
          }
          geometry Box {
            size 0.01 0.01 0.01
          }
        }
      ]
      name "ds_left"
      boundingObject USE sensor_shape
      physics Physics {
      }
      lookupTable [
        0 0 0
        0.3 30 0
      ]
    }
    DistanceSensor {
      translation 0.1 0 0
      children [
        Shape {
          appearance PBRAppearance {
            metalness 0
          }
          geometry Box {
            size 0.01 0.01 0.01
          }
        }
      ]
      name "ds_center"
      boundingObject USE sensor_shape
      physics Physics {
      }
      lookupTable [
        0 0 0
        0.29 30 0
      ]
    }
    DistanceSensor {
      translation 0.1 -0.04 0
      rotation 0 0 1 -0.5235996938995747
      children [
        Shape {
          appearance PBRAppearance {
            metalness 0
          }
          geometry Box {
            size 0.01 0.01 0.01
          }
        }
      ]
      name "ds_right"
      boundingObject USE sensor_shape
      physics Physics {
      }
      lookupTable [
        0 0 0
        0.3 30 0
      ]
    }
    Compass {
    }
    GPS {
    }
    HingeJoint {
      jointParameters HingeJointParameters {
        position 2.2047993463578495
        axis 0 1 0
        anchor 0.05 0.06 0
      }
      device [
        RotationalMotor {
          name "wheel1"
        }
      ]
      endPoint DEF Wheel1 Solid {
        translation 0.04999987479910899 0.06 -2.8030859540570134e-07
        rotation 0.33687947315228084 0.665773495430891 -0.6657761435725789 2.4917177063177345
        children [
          DEF Wheel Shape {
            appearance PBRAppearance {
              baseColor 0 1 0
              metalness 0
            }
            geometry Cylinder {
              height 0.02
              radius 0.04
            }
          }
        ]
        name "solid wheel1"
        boundingObject USE Wheel
        physics DEF Wheel_PH Physics {
        }
      }
    }
    HingeJoint {
      jointParameters HingeJointParameters {
        position 2.366400091499618
        axis 0 1 0
        anchor 0.05 -0.06 0
      }
      device [
        RotationalMotor {
          name "wheel2"
        }
      ]
      endPoint DEF Wheel2 Solid {
        translation 0.049998427923253014 -0.059999999566905826 1.174061164659025e-06
        rotation -0.2773762279067109 -0.6793597427564605 0.6793620302269772 3.6827389714547
        children [
          USE Wheel
        ]
        name "wheel2"
        boundingObject USE Wheel
        physics USE Wheel_PH
      }
    }
    HingeJoint {
      jointParameters HingeJointParameters {
        position 2.204799059788959
        axis 0 1 0
        anchor -0.05 0.06 0
      }
      device [
        RotationalMotor {
          name "wheel3"
        }
      ]
      endPoint DEF Wheel3 Solid {
        translation -0.050001740802103664 0.05999999956724689 9.04793725832726e-07
        rotation -0.3368794852963824 -0.6657736955576118 0.665775937301736 3.791467993444681
        children [
          USE Wheel
        ]
        name "wheel3"
        boundingObject USE Wheel
        physics USE Wheel_PH
      }
    }
    HingeJoint {
      jointParameters HingeJointParameters {
        position 2.3663998179324777
        axis 0 1 0
        anchor -0.05 -0.06 0
      }
      device [
        RotationalMotor {
          name "wheel4"
        }
      ]
      endPoint DEF Wheel4 Solid {
        translation -0.0500015720854401 -0.06000000043275322 1.1740495300853614e-06
        rotation -0.27737632677472557 -0.6793597225615942 0.6793620100550181 3.6827391550425483
        children [
          USE Wheel
        ]
        name "wheel4"
        boundingObject USE Wheel
        physics USE Wheel_PH
      }
    }
    DEF BODY Shape {
      appearance PBRAppearance {
        baseColor 1 0 0
        metalness 0
        IBLStrength 0
        normalMapFactor 0
        occlusionMapStrength 0
      }
      geometry Box {
        size 0.2 0.1 0.05
      }
    }
  ]
  name "robot_5"
  boundingObject USE BODY
  physics Physics {
  }
  controller "rpyc_robot"
}
Robot {
  translation -0.18946 -0.970491 0.04
  rotation 1.499569999956185e-06 7.495869999780983e-06 0.9999999999707816 1.31554
  children [
    DistanceSensor {
      translation 0.1 0.04 0
      rotation 0 0 1 0.5236003061004253
      children [
        DEF sensor_shape Shape {
          appearance PBRAppearance {
            metalness 0
          }
          geometry Box {
            size 0.01 0.01 0.01
          }
        }
      ]
      name "ds_left"
      boundingObject USE sensor_shape
      physics Physics {
      }
      lookupTable [
        0 0 0
        0.3 30 0
      ]
    }
    DistanceSensor {
      translation 0.1 0 0
      children [
        Shape {
          appearance PBRAppearance {
            metalness 0
          }
          geometry Box {
            size 0.01 0.01 0.01
          }
        }
      ]
      name "ds_center"
      boundingObject USE sensor_shape
      physics Physics {
      }
      lookupTable [
        0 0 0
        0.29 30 0
      ]
    }
    DistanceSensor {
      translation 0.1 -0.04 0
      rotation 0 0 1 -0.5236003061004253
      children [
        Shape {
          appearance PBRAppearance {
            metalness 0
          }
          geometry Box {
            size 0.01 0.01 0.01
          }
        }
      ]
      name "ds_right"
      boundingObject USE sensor_shape
      physics Physics {
      }
      lookupTable [
        0 0 0
        0.3 30 0
      ]
    }
    Compass {
    }
    GPS {
    }
    HingeJoint {
      jointParameters HingeJointParameters {
        position 2.2047993463578495
        axis 0 1 0
        anchor 0.05 0.06 0
      }
      device [
        RotationalMotor {
          name "wheel1"
        }
      ]
      endPoint DEF Wheel1 Solid {
        translation 0.04999987479910899 0.06 -2.8030859540570134e-07
        rotation 0.33687947315228084 0.665773495430891 -0.6657761435725789 2.4917177063177345
        children [
          DEF Wheel Shape {
            appearance PBRAppearance {
              baseColor 0 1 0
              metalness 0
            }
            geometry Cylinder {
              height 0.02
              radius 0.04
            }
          }
        ]
        name "solid wheel1"
        boundingObject USE Wheel
        physics DEF Wheel_PH Physics {
        }
      }
    }
    HingeJoint {
      jointParameters HingeJointParameters {
        position 2.366400091499618
        axis 0 1 0
        anchor 0.05 -0.06 0
      }
      device [
        RotationalMotor {
          name "wheel2"
        }
      ]
      endPoint DEF Wheel2 Solid {
        translation 0.049998427923253014 -0.059999999566905826 1.174061164659025e-06
        rotation -0.2773762279067109 -0.6793597427564605 0.6793620302269772 3.6827389714547
        children [
          USE Wheel
        ]
        name "wheel2"
        boundingObject USE Wheel
        physics USE Wheel_PH
      }
    }
    HingeJoint {
      jointParameters HingeJointParameters {
        position 2.204799059788959
        axis 0 1 0
        anchor -0.05 0.06 0
      }
      device [
        RotationalMotor {
          name "wheel3"
        }
      ]
      endPoint DEF Wheel3 Solid {
        translation -0.050001740802103664 0.05999999956724689 9.04793725832726e-07
        rotation -0.3368794852963824 -0.6657736955576118 0.665775937301736 3.791467993444681
        children [
          USE Wheel
        ]
        name "wheel3"
        boundingObject USE Wheel
        physics USE Wheel_PH
      }
    }
    HingeJoint {
      jointParameters HingeJointParameters {
        position 2.3663998179324777
        axis 0 1 0
        anchor -0.05 -0.06 0
      }
      device [
        RotationalMotor {
          name "wheel4"
        }
      ]
      endPoint DEF Wheel4 Solid {
        translation -0.0500015720854401 -0.06000000043275322 1.1740495300853614e-06
        rotation -0.27737632677472557 -0.6793597225615942 0.6793620100550181 3.6827391550425483
        children [
          USE Wheel
        ]
        name "wheel4"
        boundingObject USE Wheel
        physics USE Wheel_PH
      }
    }
    DEF BODY Shape {
      appearance PBRAppearance {
        baseColor 1 0 0
        metalness 0
        IBLStrength 0
        normalMapFactor 0
        occlusionMapStrength 0
      }
      geometry Box {
        size 0.2 0.1 0.05
      }
    }
  ]
  name "robot_1"
  boundingObject USE BODY
  physics Physics {
  }
  controller "rpyc_robot"
}
Solid {
  translation 0 1.5 0
  rotation 0 1 0 0
  children [
    DEF muro Shape {
      appearance PBRAppearance {
        baseColor 0 0 1
        roughness 0.5
        metalness 0
      }
      geometry Box {
        size 3 0.02 0.1
      }
    }
  ]
  name "muro 1 (DEF)"
  boundingObject USE muro
}
Solid {
  translation 0 -1.5 0
  children [
    USE muro
  ]
  name "muro 2"
  boundingObject USE muro
}
Solid {
  translation -1.5 0 0
  rotation 0 0 1 1.5708
  children [
    USE muro
  ]
  name "muro 3"
  boundingObject USE muro
}
Solid {
  translation 1.5 0 0
  rotation 0 0 1 1.5707996938995747
  children [
    USE muro
  ]
  name "muro 4"
  boundingObject USE muro
}
Robot {
  translation -1.02462 -0.851939 0.0398594
  rotation 1.1581399999136349e-05 3.87501999971103e-06 -0.9999999999254277 0.785389
  children [
    DistanceSensor {
      translation 0.1 0.04 0
      rotation 0 0 1 0.5236003061004253
      children [
        DEF sensor_shape Shape {
          appearance PBRAppearance {
            metalness 0
          }
          geometry Box {
            size 0.01 0.01 0.01
          }
        }
      ]
      name "ds_left"
      boundingObject USE sensor_shape
      physics Physics {
      }
      lookupTable [
        0 0 0
        0.3 30 0
      ]
    }
    DistanceSensor {
      translation 0.1 0 0
      children [
        Shape {
          appearance PBRAppearance {
            metalness 0
          }
          geometry Box {
            size 0.01 0.01 0.01
          }
        }
      ]
      name "ds_center"
      boundingObject USE sensor_shape
      physics Physics {
      }
      lookupTable [
        0 0 0
        0.29 30 0
      ]
    }
    DistanceSensor {
      translation 0.1 -0.04 0
      rotation 0 0 1 -0.5235996938995747
      children [
        Shape {
          appearance PBRAppearance {
            metalness 0
          }
          geometry Box {
            size 0.01 0.01 0.01
          }
        }
      ]
      name "ds_right"
      boundingObject USE sensor_shape
      physics Physics {
      }
      lookupTable [
        0 0 0
        0.3 30 0
      ]
    }
    Compass {
    }
    GPS {
    }
    HingeJoint {
      jointParameters HingeJointParameters {
        position 2.2047993463578495
        axis 0 1 0
        anchor 0.05 0.06 0
      }
      device [
        RotationalMotor {
          name "wheel1"
        }
      ]
      endPoint DEF Wheel1 Solid {
        translation 0.04999987479910899 0.06 -2.8030859540570134e-07
        rotation 0.33687947315228084 0.665773495430891 -0.6657761435725789 2.4917177063177345
        children [
          DEF Wheel Shape {
            appearance PBRAppearance {
              baseColor 0 1 0
              metalness 0
            }
            geometry Cylinder {
              height 0.02
              radius 0.04
            }
          }
        ]
        name "solid wheel1"
        boundingObject USE Wheel
        physics DEF Wheel_PH Physics {
        }
      }
    }
    HingeJoint {
      jointParameters HingeJointParameters {
        position 2.366400091499618
        axis 0 1 0
        anchor 0.05 -0.06 0
      }
      device [
        RotationalMotor {
          name "wheel2"
        }
      ]
      endPoint DEF Wheel2 Solid {
        translation 0.049998427923253014 -0.059999999566905826 1.174061164659025e-06
        rotation -0.2773762279067109 -0.6793597427564605 0.6793620302269772 3.6827389714547
        children [
          USE Wheel
        ]
        name "wheel2"
        boundingObject USE Wheel
        physics USE Wheel_PH
      }
    }
    HingeJoint {
      jointParameters HingeJointParameters {
        position 2.204799059788959
        axis 0 1 0
        anchor -0.05 0.06 0
      }
      device [
        RotationalMotor {
          name "wheel3"
        }
      ]
      endPoint DEF Wheel3 Solid {
        translation -0.050001740802103664 0.05999999956724689 9.04793725832726e-07
        rotation -0.3368794852963824 -0.6657736955576118 0.665775937301736 3.791467993444681
        children [
          USE Wheel
        ]
        name "wheel3"
        boundingObject USE Wheel
        physics USE Wheel_PH
      }
    }
    HingeJoint {
      jointParameters HingeJointParameters {
        position 2.3663998179324777
        axis 0 1 0
        anchor -0.05 -0.06 0
      }
      device [
        RotationalMotor {
          name "wheel4"
        }
      ]
      endPoint DEF Wheel4 Solid {
        translation -0.0500015720854401 -0.06000000043275322 1.1740495300853614e-06
        rotation -0.27737632677472557 -0.6793597225615942 0.6793620100550181 3.6827391550425483
        children [
          USE Wheel
        ]
        name "wheel4"
        boundingObject USE Wheel
        physics USE Wheel_PH
      }
    }
    DEF BODY Shape {
      appearance PBRAppearance {
        baseColor 1 0 0
        metalness 0
        IBLStrength 0
        normalMapFactor 0
        occlusionMapStrength 0
      }
      geometry Box {
        size 0.2 0.1 0.05
      }
    }
  ]
  name "robot_2"
  boundingObject USE BODY
  physics Physics {
  }
  controller "rpyc_robot"
}
Robot {
  translation -0.49942 0.00349876 0.04
  rotation -2.85802999996868e-06 3.7079299999593666e-06 0.9999999999890414 3.02378
  children [
    DistanceSensor {
      translation 0.1 0.04 0
      rotation 0 0 1 0.5235996938995747
      children [
        DEF sensor_shape Shape {
          appearance PBRAppearance {
            metalness 0
          }
          geometry Box {
            size 0.01 0.01 0.01
          }
        }
      ]
      name "ds_left"
      boundingObject USE sensor_shape
      physics Physics {
      }
      lookupTable [
        0 0 0
        0.3 30 0
      ]
    }
    DistanceSensor {
      translation 0.1 0 0
      children [
        Shape {
          appearance PBRAppearance {
            metalness 0
          }
          geometry Box {
            size 0.01 0.01 0.01
          }
        }
      ]
      name "ds_center"
      boundingObject USE sensor_shape
      physics Physics {
      }
      lookupTable [
        0 0 0
        0.29 30 0
      ]
    }
    DistanceSensor {
      translation 0.1 -0.04 0
      rotation 0 0 1 -0.5235996938995747
      children [
        Shape {
          appearance PBRAppearance {
            metalness 0
          }
          geometry Box {
            size 0.01 0.01 0.01
          }
        }
      ]
      name "ds_right"
      boundingObject USE sensor_shape
      physics Physics {
      }
      lookupTable [
        0 0 0
        0.3 30 0
      ]
    }
    Compass {
    }
    GPS {
    }
    HingeJoint {
      jointParameters HingeJointParameters {
        position 2.2047993463578495
        axis 0 1 0
        anchor 0.05 0.06 0
      }
      device [
        RotationalMotor {
          name "wheel1"
        }
      ]
      endPoint DEF Wheel1 Solid {
        translation 0.04999987479910899 0.06 -2.8030859540570134e-07
        rotation 0.33687947315228084 0.665773495430891 -0.6657761435725789 2.4917177063177345
        children [
          DEF Wheel Shape {
            appearance PBRAppearance {
              baseColor 0 1 0
              metalness 0
            }
            geometry Cylinder {
              height 0.02
              radius 0.04
            }
          }
        ]
        name "solid wheel1"
        boundingObject USE Wheel
        physics DEF Wheel_PH Physics {
        }
      }
    }
    HingeJoint {
      jointParameters HingeJointParameters {
        position 2.366400091499618
        axis 0 1 0
        anchor 0.05 -0.06 0
      }
      device [
        RotationalMotor {
          name "wheel2"
        }
      ]
      endPoint DEF Wheel2 Solid {
        translation 0.049998427923253014 -0.059999999566905826 1.174061164659025e-06
        rotation -0.2773762279067109 -0.6793597427564605 0.6793620302269772 3.6827389714547
        children [
          USE Wheel
        ]
        name "wheel2"
        boundingObject USE Wheel
        physics USE Wheel_PH
      }
    }
    HingeJoint {
      jointParameters HingeJointParameters {
        position 2.204799059788959
        axis 0 1 0
        anchor -0.05 0.06 0
      }
      device [
        RotationalMotor {
          name "wheel3"
        }
      ]
      endPoint DEF Wheel3 Solid {
        translation -0.050001740802103664 0.05999999956724689 9.04793725832726e-07
        rotation -0.3368794852963824 -0.6657736955576118 0.665775937301736 3.791467993444681
        children [
          USE Wheel
        ]
        name "wheel3"
        boundingObject USE Wheel
        physics USE Wheel_PH
      }
    }
    HingeJoint {
      jointParameters HingeJointParameters {
        position 2.3663998179324777
        axis 0 1 0
        anchor -0.05 -0.06 0
      }
      device [
        RotationalMotor {
          name "wheel4"
        }
      ]
      endPoint DEF Wheel4 Solid {
        translation -0.0500015720854401 -0.06000000043275322 1.1740495300853614e-06
        rotation -0.27737632677472557 -0.6793597225615942 0.6793620100550181 3.6827391550425483
        children [
          USE Wheel
        ]
        name "wheel4"
        boundingObject USE Wheel
        physics USE Wheel_PH
      }
    }
    DEF BODY Shape {
      appearance PBRAppearance {
        baseColor 1 0 0
        metalness 0
        IBLStrength 0
        normalMapFactor 0
        occlusionMapStrength 0
      }
      geometry Box {
        size 0.2 0.1 0.05
      }
    }
  ]
  name "robot_3"
  boundingObject USE BODY
  physics Physics {
  }
  controller "rpyc_robot"
}
Solid {
  children [
    Shape {
      appearance PBRAppearance {
        metalness 0
      }
      geometry Cylinder {
        height 0.6
        radius 0.02
      }
    }
  ]
}
