#VRML_SIM R2023b utf8

EXTERNPROTO "https://raw.githubusercontent.com/cyberbotics/webots/R2023a/projects/objects/backgrounds/protos/TexturedBackground.proto"
EXTERNPROTO "https://raw.githubusercontent.com/cyberbotics/webots/R2023a/projects/objects/backgrounds/protos/TexturedBackgroundLight.proto"
EXTERNPROTO "https://raw.githubusercontent.com/cyberbotics/webots/R2023a/projects/appearances/protos/VarnishedPine.proto"
EXTERNPROTO "https://raw.githubusercontent.com/cyberbotics/webots/R2023a/projects/objects/floors/protos/Floor.proto"

WorldInfo {
}
Viewpoint {
  orientation 0.0039243540594594084 -0.9999567621524812 -0.008430496470687011 5.411103035470998
  position -6.219547461464753 -0.030140684862213975 6.842182794965026
}
TexturedBackground {
}
Floor {
  name "floor_1"
  size 4 6
  tileSize 4 6
  appearance PBRAppearance {
    baseColorMap ImageTexture {
      url [
        "../mapa_2.jpg"
      ]
    }
    metalness 0
  }
}
TexturedBackgroundLight {
}
DEF robot_1 Robot {
  translation -1.64348 -0.208726 0.0396148
  rotation 0.0003453489344281814 -0.0005103689030956409 -0.9999998101288302 0.575584
  children [
    Solid {
      translation 0.095 0 0.04
      children [
        DEF cuerpo_camara Shape {
          appearance PBRAppearance {
            metalness 0
          }
          geometry Box {
            size 0.01 0.01 0.03
          }
        }
      ]
      name "cuerpo_camara"
      boundingObject USE cuerpo_camara
      physics Physics {
      }
    }
    Camera {
      translation 0.095 0 0.06
      children [
        Shape {
          appearance PBRAppearance {
            baseColor 0 0 0
            metalness 0
          }
          geometry Box {
            size 0.01 0.01 0.01
          }
        }
      ]
      width 1200
      height 1200
      antiAliasing TRUE
      recognition Recognition {
        frameThickness 10
      }
    }
    DistanceSensor {
      translation 0.1 0.02 0
      rotation 0 0 1 0.26180030610042526
      children [
        DEF sensor_shape Shape {
          appearance PBRAppearance {
            baseColor 0 0 1
            metalness 0
          }
          geometry Box {
            size 0.01 0.01 0.01
          }
        }
      ]
      name "ds_left_1"
      boundingObject USE sensor_shape
      physics Physics {
      }
      recognitionColors [
        0 0 0
      ]
      lookupTable [
        0 0 0
        0.3 30 0
      ]
    }
    DistanceSensor {
      translation 0.1 0.04 0
      rotation 0 0 1 0.5235996938995747
      children [
        DEF sensor_shape Shape {
          appearance PBRAppearance {
            baseColor 0 0 1
            metalness 0
          }
          geometry Box {
            size 0.01 0.01 0.01
          }
        }
      ]
      name "ds_left_2"
      boundingObject USE sensor_shape
      physics Physics {
      }
      recognitionColors [
        0 0 0
      ]
      lookupTable [
        0 0 0
        0.3 30 0
      ]
    }
    DistanceSensor {
      translation 0.1 0 0
      children [
        DEF sensor_shape Shape {
          appearance PBRAppearance {
            baseColor 0 0 1
            metalness 0
          }
          geometry Box {
            size 0.01 0.01 0.01
          }
        }
      ]
      name "ds_center"
      boundingObject USE sensor_shape
      physics Physics {
      }
      lookupTable [
        0 0 0
        0.29 30 0
      ]
    }
    DistanceSensor {
      translation 0.1 -0.02 0
      rotation 0 0 1 -0.2617996938995747
      children [
        DEF sensor_shape Shape {
          appearance PBRAppearance {
            baseColor 0 0 1
            metalness 0
          }
          geometry Box {
            size 0.01 0.01 0.01
          }
        }
      ]
      name "ds_right_1"
      boundingObject USE sensor_shape
      physics Physics {
      }
      lookupTable [
        0 0 0
        0.3 30 0
      ]
    }
    DistanceSensor {
      translation 0.1 -0.04 0
      rotation 0 0 1 -0.5235996938995747
      children [
        DEF sensor_shape Shape {
          appearance PBRAppearance {
            baseColor 0 0 1
            metalness 0
          }
          geometry Box {
            size 0.01 0.01 0.01
          }
        }
      ]
      name "ds_right_2"
      boundingObject USE sensor_shape
      physics Physics {
      }
      lookupTable [
        0 0 0
        0.3 30 0
      ]
    }
    HingeJoint {
      jointParameters HingeJointParameters {
        position 17.0207732809251
        axis 0 1 0
        anchor 0.05 0.06 0
      }
      device [
        RotationalMotor {
          name "wheel1"
        }
      ]
      endPoint DEF Wheel1 Solid {
        translation 0.0499998604388116 0.06 2.7344258363222877e-07
        rotation -0.4783333706664932 0.6209646197912162 -0.6209670904922268 4.033918661596566
        children [
          DEF Wheel Shape {
            appearance PBRAppearance {
              baseColor 0 1 0
              metalness 0
            }
            geometry Cylinder {
              height 0.02
              radius 0.04
            }
          }
        ]
        name "solid wheel1"
        boundingObject USE Wheel
        physics DEF Wheel_PH Physics {
        }
      }
    }
    HingeJoint {
      jointParameters HingeJointParameters {
        position 8.734415423406244
        axis 0 1 0
        anchor 0.05 -0.06 0
      }
      device [
        RotationalMotor {
          name "wheel2"
        }
      ]
      endPoint DEF Wheel2 Solid {
        translation 0.049998533052528486 -0.059999999566905826 1.3030387688304735e-06
        rotation 0.24644521748245493 0.6852961375152874 -0.6852984449760949 2.65833382375026
        children [
          USE Wheel
        ]
        name "wheel2"
        boundingObject USE Wheel
        physics USE Wheel_PH
      }
    }
    HingeJoint {
      jointParameters HingeJointParameters {
        position 17.02078430584313
        axis 0 1 0
        anchor -0.05 0.06 0
      }
      device [
        RotationalMotor {
          name "wheel3"
        }
      ]
      endPoint DEF Wheel3 Solid {
        translation -0.04999820278136183 0.05999999956724689 7.867965550065733e-07
        rotation 0.4783374671267055 -0.62096323191948 0.6209653228215907 2.249259503561873
        children [
          USE Wheel
        ]
        name "wheel3"
        boundingObject USE Wheel
        physics USE Wheel_PH
      }
    }
    HingeJoint {
      jointParameters HingeJointParameters {
        position 8.734426201659975
        axis 0 1 0
        anchor -0.05 -0.06 0
      }
      device [
        RotationalMotor {
          name "wheel4"
        }
      ]
      endPoint DEF Wheel4 Solid {
        translation -0.0500014669427183 -0.06000000043275322 1.303044125204761e-06
        rotation 0.24644129882066124 0.6852968421071951 -0.6852991495934397 2.658341212330911
        children [
          USE Wheel
        ]
        name "wheel4"
        boundingObject USE Wheel
        physics USE Wheel_PH
      }
    }
    DEF BODY Shape {
      appearance PBRAppearance {
        baseColor 1 0 0
        metalness 0
        IBLStrength 0
        normalMapFactor 0
        occlusionMapStrength 0
      }
      geometry Box {
        size 0.2 0.1 0.05
      }
    }
  ]
  name "robot_1"
  model "robot"
  boundingObject USE BODY
  physics Physics {
  }
  recognitionColors [
    1 1 1
  ]
  controller "searcher"
}
DEF robot_2 Robot {
  translation 1.39366 -0.0781088 0.039615
  rotation -0.00016590499687456144 -0.00010076199810177246 -0.9999999811612758 2.24456
  children [
    Solid {
      translation 0.095 0 0.04
      children [
        DEF cuerpo_camara Shape {
          appearance PBRAppearance {
            metalness 0
          }
          geometry Box {
            size 0.01 0.01 0.03
          }
        }
      ]
      name "cuerpo_camara"
      boundingObject USE cuerpo_camara
      physics Physics {
      }
    }
    Camera {
      translation 0.095 0 0.06
      children [
        Shape {
          appearance PBRAppearance {
            baseColor 0 0 0
            metalness 0
          }
          geometry Box {
            size 0.01 0.01 0.01
          }
        }
      ]
      width 1200
      height 1200
      antiAliasing TRUE
      recognition Recognition {
        frameThickness 10
      }
    }
    DistanceSensor {
      translation 0.1 0.02 0
      rotation 0 0 1 0.26180030610042526
      children [
        DEF sensor_shape Shape {
          appearance PBRAppearance {
            baseColor 0 0 1
            metalness 0
          }
          geometry Box {
            size 0.01 0.01 0.01
          }
        }
      ]
      name "ds_left_1"
      boundingObject USE sensor_shape
      physics Physics {
      }
      recognitionColors [
        0 0 0
      ]
      lookupTable [
        0 0 0
        0.3 30 0
      ]
    }
    DistanceSensor {
      translation 0.1 0.04 0
      rotation 0 0 1 0.5235996938995747
      children [
        DEF sensor_shape Shape {
          appearance PBRAppearance {
            baseColor 0 0 1
            metalness 0
          }
          geometry Box {
            size 0.01 0.01 0.01
          }
        }
      ]
      name "ds_left_2"
      boundingObject USE sensor_shape
      physics Physics {
      }
      recognitionColors [
        0 0 0
      ]
      lookupTable [
        0 0 0
        0.3 30 0
      ]
    }
    DistanceSensor {
      translation 0.1 0 0
      children [
        DEF sensor_shape Shape {
          appearance PBRAppearance {
            baseColor 0 0 1
            metalness 0
          }
          geometry Box {
            size 0.01 0.01 0.01
          }
        }
      ]
      name "ds_center"
      boundingObject USE sensor_shape
      physics Physics {
      }
      lookupTable [
        0 0 0
        0.29 30 0
      ]
    }
    DistanceSensor {
      translation 0.1 -0.02 0
      rotation 0 0 1 -0.2617996938995747
      children [
        DEF sensor_shape Shape {
          appearance PBRAppearance {
            baseColor 0 0 1
            metalness 0
          }
          geometry Box {
            size 0.01 0.01 0.01
          }
        }
      ]
      name "ds_right_1"
      boundingObject USE sensor_shape
      physics Physics {
      }
      lookupTable [
        0 0 0
        0.3 30 0
      ]
    }
    DistanceSensor {
      translation 0.1 -0.04 0
      rotation 0 0 1 -0.5235996938995747
      children [
        DEF sensor_shape Shape {
          appearance PBRAppearance {
            baseColor 0 0 1
            metalness 0
          }
          geometry Box {
            size 0.01 0.01 0.01
          }
        }
      ]
      name "ds_right_2"
      boundingObject USE sensor_shape
      physics Physics {
      }
      lookupTable [
        0 0 0
        0.3 30 0
      ]
    }
    HingeJoint {
      jointParameters HingeJointParameters {
        position 17.0207732809251
        axis 0 1 0
        anchor 0.05 0.06 0
      }
      device [
        RotationalMotor {
          name "wheel1"
        }
      ]
      endPoint DEF Wheel1 Solid {
        translation 0.0499998604388116 0.06 2.7344258363222877e-07
        rotation -0.4783333706664932 0.6209646197912162 -0.6209670904922268 4.033918661596566
        children [
          DEF Wheel Shape {
            appearance PBRAppearance {
              baseColor 0 1 0
              metalness 0
            }
            geometry Cylinder {
              height 0.02
              radius 0.04
            }
          }
        ]
        name "solid wheel1"
        boundingObject USE Wheel
        physics DEF Wheel_PH Physics {
        }
      }
    }
    HingeJoint {
      jointParameters HingeJointParameters {
        position 8.734415423406244
        axis 0 1 0
        anchor 0.05 -0.06 0
      }
      device [
        RotationalMotor {
          name "wheel2"
        }
      ]
      endPoint DEF Wheel2 Solid {
        translation 0.049998533052528486 -0.059999999566905826 1.3030387688304735e-06
        rotation 0.24644521748245493 0.6852961375152874 -0.6852984449760949 2.65833382375026
        children [
          USE Wheel
        ]
        name "wheel2"
        boundingObject USE Wheel
        physics USE Wheel_PH
      }
    }
    HingeJoint {
      jointParameters HingeJointParameters {
        position 17.02078430584313
        axis 0 1 0
        anchor -0.05 0.06 0
      }
      device [
        RotationalMotor {
          name "wheel3"
        }
      ]
      endPoint DEF Wheel3 Solid {
        translation -0.04999820278136183 0.05999999956724689 7.867965550065733e-07
        rotation 0.4783374671267055 -0.62096323191948 0.6209653228215907 2.249259503561873
        children [
          USE Wheel
        ]
        name "wheel3"
        boundingObject USE Wheel
        physics USE Wheel_PH
      }
    }
    HingeJoint {
      jointParameters HingeJointParameters {
        position 8.734426201659975
        axis 0 1 0
        anchor -0.05 -0.06 0
      }
      device [
        RotationalMotor {
          name "wheel4"
        }
      ]
      endPoint DEF Wheel4 Solid {
        translation -0.0500014669427183 -0.06000000043275322 1.303044125204761e-06
        rotation 0.24644129882066124 0.6852968421071951 -0.6852991495934397 2.658341212330911
        children [
          USE Wheel
        ]
        name "wheel4"
        boundingObject USE Wheel
        physics USE Wheel_PH
      }
    }
    DEF BODY Shape {
      appearance PBRAppearance {
        baseColor 1 0 0
        metalness 0
        IBLStrength 0
        normalMapFactor 0
        occlusionMapStrength 0
      }
      geometry Box {
        size 0.2 0.1 0.05
      }
    }
  ]
  name "robot_2"
  model "robot"
  boundingObject USE BODY
  physics Physics {
  }
  recognitionColors [
    1 1 1
  ]
  controller "searcher"
}
DEF robot_3 Robot {
  translation -0.00541795 1.11805 0.039615
  rotation -0.00015683899513777122 -0.00019340199400426697 -0.9999999689985987 1.55735
  children [
    DistanceSensor {
      translation 0.09 0.04 -0.027
      rotation 0 1 0 1.5707996938995747
      children [
        Shape {
          appearance PBRAppearance {
            baseColor 1 0 0
            metalness 0
          }
          geometry Box {
            size 0.005 0.01 0.01
          }
        }
      ]
      name "ir_left"
      type "infra-red"
    }
    DistanceSensor {
      translation 0.09 -0.04 -0.027
      rotation 0 1 0 1.5707996938995747
      children [
        Shape {
          appearance PBRAppearance {
            baseColor 1 0 0
            metalness 0
          }
          geometry Box {
            size 0.005 0.01 0.01
          }
        }
      ]
      name "ir_right"
      type "infra-red"
    }
    DistanceSensor {
      translation 0.1 0 0
      children [
        DEF sensor_shape Shape {
          appearance PBRAppearance {
            baseColor 0 0 1
            metalness 0
          }
          geometry Box {
            size 0.01 0.01 0.01
          }
        }
      ]
      name "ds_center"
      boundingObject USE sensor_shape
      physics Physics {
      }
      lookupTable [
        0 0 0
        0.1 100 0
      ]
    }
    HingeJoint {
      jointParameters HingeJointParameters {
        position 17.0207732809251
        axis 0 1 0
        anchor 0.05 0.06 0
      }
      device [
        RotationalMotor {
          name "wheel1"
        }
      ]
      endPoint DEF Wheel1 Solid {
        translation 0.04999986043881162 0.06 2.7344258363772157e-07
        rotation -0.4783333706664896 0.620964619791224 -0.6209670904922218 4.033918661596599
        children [
          DEF Wheel Shape {
            appearance PBRAppearance {
              baseColor 0 1 0
              metalness 0
            }
            geometry Cylinder {
              height 0.02
              radius 0.04
            }
          }
        ]
        name "solid wheel1"
        boundingObject USE Wheel
        physics DEF Wheel_PH Physics {
        }
      }
    }
    HingeJoint {
      jointParameters HingeJointParameters {
        position 8.734415423406244
        axis 0 1 0
        anchor 0.05 -0.06 0
      }
      device [
        RotationalMotor {
          name "wheel2"
        }
      ]
      endPoint DEF Wheel2 Solid {
        translation 0.0499985330525285 -0.059999999566905826 1.3030387688136718e-06
        rotation 0.24644521748245599 0.6852961375152873 -0.6852984449760947 2.658333823750258
        children [
          USE Wheel
        ]
        name "wheel2"
        boundingObject USE Wheel
        physics USE Wheel_PH
      }
    }
    HingeJoint {
      jointParameters HingeJointParameters {
        position 17.02078430584313
        axis 0 1 0
        anchor -0.05 0.06 0
      }
      device [
        RotationalMotor {
          name "wheel3"
        }
      ]
      endPoint DEF Wheel3 Solid {
        translation -0.04999820278136177 0.05999999956724689 7.867965550212202e-07
        rotation 0.4783374671267053 -0.6209632319194787 0.6209653228215918 2.249259503561871
        children [
          USE Wheel
        ]
        name "wheel3"
        boundingObject USE Wheel
        physics USE Wheel_PH
      }
    }
    HingeJoint {
      jointParameters HingeJointParameters {
        position 8.734426201659975
        axis 0 1 0
        anchor -0.05 -0.06 0
      }
      device [
        RotationalMotor {
          name "wheel4"
        }
      ]
      endPoint DEF Wheel4 Solid {
        translation -0.050001466942718314 -0.06000000043275322 1.3030441252215638e-06
        rotation 0.24644129882065988 0.6852968421071944 -0.6852991495934411 2.6583412123308983
        children [
          USE Wheel
        ]
        name "wheel4"
        boundingObject USE Wheel
        physics USE Wheel_PH
      }
    }
    DEF BODY Shape {
      appearance PBRAppearance {
        baseColor 0.333333 0.666667 1
        metalness 0
        IBLStrength 0
        normalMapFactor 0
        occlusionMapStrength 0
      }
      geometry Box {
        size 0.2 0.1 0.05
      }
    }
  ]
  name "robot_3"
  model "robot"
  boundingObject USE BODY
  physics Physics {
  }
  controller "liner"
}
DEF robot_4 Robot {
  translation -0.00564959 1.40092 0.039721
  rotation -8.07718440983607e-06 6.998044323835482e-06 -0.9999999999428931 1.5573692441762284
  children [
    DistanceSensor {
      translation 0.09 0.04 -0.027
      rotation 0 1 0 1.5707996938995747
      children [
        Shape {
          appearance PBRAppearance {
            baseColor 1 0 0
            metalness 0
          }
          geometry Box {
            size 0.005 0.01 0.01
          }
        }
      ]
      name "ir_left"
      type "infra-red"
    }
    DistanceSensor {
      translation 0.09 -0.04 -0.027
      rotation 0 1 0 1.5707996938995747
      children [
        Shape {
          appearance PBRAppearance {
            baseColor 1 0 0
            metalness 0
          }
          geometry Box {
            size 0.005 0.01 0.01
          }
        }
      ]
      name "ir_right"
      type "infra-red"
    }
    DistanceSensor {
      translation 0.1 0 0
      children [
        DEF sensor_shape Shape {
          appearance PBRAppearance {
            baseColor 0 0 1
            metalness 0
          }
          geometry Box {
            size 0.01 0.01 0.01
          }
        }
      ]
      name "ds_center"
      boundingObject USE sensor_shape
      physics Physics {
      }
      lookupTable [
        0 0 0
        0.1 100 0
      ]
    }
    HingeJoint {
      jointParameters HingeJointParameters {
        position 20.692950862653667
        axis 0 1 0
        anchor 0.05 0.06 0
      }
      device [
        RotationalMotor {
          name "wheel1"
        }
      ]
      endPoint DEF Wheel1 Solid {
        translation 0.049999982000770854 0.06 -3.0647055258161153e-07
        rotation -0.4728151157584073 -0.6230741441296407 0.6230766222764897 4.024917894291292
        children [
          DEF Wheel Shape {
            appearance PBRAppearance {
              baseColor 0 1 0
              metalness 0
            }
            geometry Cylinder {
              height 0.02
              radius 0.04
            }
          }
        ]
        name "solid wheel1"
        boundingObject USE Wheel
        physics DEF Wheel_PH Physics {
        }
      }
    }
    HingeJoint {
      jointParameters HingeJointParameters {
        position 12.406593009285935
        axis 0 1 0
        anchor 0.05 -0.06 0
      }
      device [
        RotationalMotor {
          name "wheel2"
        }
      ]
      endPoint DEF Wheel2 Solid {
        translation 0.050000605871601315 -0.059999999566905826 -1.866216632629998e-06
        rotation -0.9936458992859802 0.07958575302939262 -0.07958602105206733 4.706011282576193
        children [
          USE Wheel
        ]
        name "wheel2"
        boundingObject USE Wheel
        physics USE Wheel_PH
      }
    }
    HingeJoint {
      jointParameters HingeJointParameters {
        position 20.692961676432787
        axis 0 1 0
        anchor -0.05 0.06 0
      }
      device [
        RotationalMotor {
          name "wheel3"
        }
      ]
      endPoint DEF Wheel3 Solid {
        translation -0.05000194827019689 0.05999999956724689 2.308395384321078e-07
        rotation 0.472810878713391 0.623075941832039 -0.6230780397995009 2.258273865593935
        children [
          USE Wheel
        ]
        name "wheel3"
        boundingObject USE Wheel
        physics USE Wheel_PH
      }
    }
    HingeJoint {
      jointParameters HingeJointParameters {
        position 12.406603787092319
        axis 0 1 0
        anchor -0.05 -0.06 0
      }
      device [
        RotationalMotor {
          name "wheel4"
        }
      ]
      endPoint DEF Wheel4 Solid {
        translation -0.04999939413520808 -0.06000000043275322 -1.8662188470259506e-06
        rotation -0.9936467518469898 0.07958043065712328 -0.07958069866716211 4.706012140536917
        children [
          USE Wheel
        ]
        name "wheel4"
        boundingObject USE Wheel
        physics USE Wheel_PH
      }
    }
    DEF BODY Shape {
      appearance PBRAppearance {
        baseColor 0.333333 0.666667 1
        metalness 0
        IBLStrength 0
        normalMapFactor 0
        occlusionMapStrength 0
      }
      geometry Box {
        size 0.2 0.1 0.05
      }
    }
  ]
  name "robot_4"
  model "robot"
  boundingObject USE BODY
  physics Physics {
  }
  controller "liner"
}
Robot {
  name "supervisor"
  controller "supervisor"
  supervisor TRUE
}
DEF box_1 Solid {
  translation 0.254905 -1.70801 0.0496118
  rotation -4.1680976249909065e-12 -4.333274753177387e-12 -1 6.045649790545454e-06
  children [
    DEF BOX_SHAPE Shape {
      appearance PBRAppearance {
        baseColor 1 0 0
        metalness 0
      }
      geometry Box {
        size 0.1 0.1 0.1
      }
    }
  ]
  name "box_1"
  model "box_1"
  boundingObject USE BOX_SHAPE
  physics DEF box_phy Physics {
    density -1
    mass 0.5
  }
  recognitionColors [
    1 0 0
  ]
}
DEF box_2 Solid {
  translation 0.75257 -1.63795 0.0496118
  rotation 5.627928571461135e-12 2.4997518137144247e-12 -0.9999999999999999 6.045625161073053e-06
  children [
    DEF BOX_SHAPE Shape {
      appearance PBRAppearance {
        baseColor 0 0 1
        metalness 0
      }
      geometry Box {
        size 0.1 0.1 0.1
      }
    }
  ]
  name "box_2"
  model "box_2"
  boundingObject USE BOX_SHAPE
  physics USE box_phy
  recognitionColors [
    0 0 1
  ]
}
DEF box_4 Solid {
  translation 0.869644 -1.2867 0.0496118
  rotation -1.89666e-16 1.70455e-16 -1 0.340345
  children [
    DEF BOX_SHAPE Shape {
      appearance PBRAppearance {
        baseColor 0 0 1
        metalness 0
      }
      geometry Box {
        size 0.1 0.1 0.1
      }
    }
  ]
  name "box_4"
  model "box_4"
  boundingObject USE BOX_SHAPE
  physics USE box_phy
  recognitionColors [
    0 0 1
  ]
}
DEF box_5 Solid {
  translation -0.090878 -0.461098 0.0496118
  rotation -1.14869e-16 -1.28563e-16 1 0.287973
  children [
    DEF BOX_SHAPE Shape {
      appearance PBRAppearance {
        baseColor 1 0 0
        metalness 0
      }
      geometry Box {
        size 0.1 0.1 0.1
      }
    }
  ]
  name "box_5"
  model "box_5"
  boundingObject USE BOX_SHAPE
  physics USE box_phy
  recognitionColors [
    1 0 0
  ]
}
DEF box_6 Solid {
  translation 1.32076 -1.35469 0.0496118
  rotation -1.192507954931382e-11 5.2747457082485944e-12 -1 6.0456497905797125e-06
  children [
    DEF BOX_SHAPE Shape {
      appearance PBRAppearance {
        baseColor 1 0 0
        metalness 0
      }
      geometry Box {
        size 0.1 0.1 0.1
      }
    }
  ]
  name "box_6"
  model "box_6"
  boundingObject USE BOX_SHAPE
  physics USE box_phy
  recognitionColors [
    1 0 0
  ]
}
DEF box_7 Solid {
  translation 0.789279 -0.78087 0.0496118
  rotation -1.34740027621794e-12 -1.0220101886933985e-13 -0.9999999999999999 6.0456497906023715e-06
  children [
    DEF BOX_SHAPE Shape {
      appearance PBRAppearance {
        baseColor 1 0 0
        metalness 0
      }
      geometry Box {
        size 0.1 0.1 0.1
      }
    }
  ]
  name "box_7"
  model "box_7"
  boundingObject USE BOX_SHAPE
  physics USE box_phy
  recognitionColors [
    1 0 0
  ]
}
DEF box_8 Solid {
  translation -0.884479 -0.910668 0.0496118
  rotation -1.7881322385671303e-12 -1.4244102285689888e-12 -1 6.045649790565141e-06
  children [
    DEF BOX_SHAPE Shape {
      appearance PBRAppearance {
        baseColor 1 0 0
        metalness 0
      }
      geometry Box {
        size 0.1 0.1 0.1
      }
    }
  ]
  name "box_8"
  model "box_8"
  boundingObject USE BOX_SHAPE
  physics USE box_phy
  recognitionColors [
    1 0 0
  ]
}
DEF box_9 Solid {
  translation 0.536187 -2.21105 0.049554
  rotation -0.013896508657903072 0.9995180783940972 0.02775784592673378 0.0003906899320571952
  children [
    DEF BOX_SHAPE Shape {
      appearance PBRAppearance {
        baseColor 1 0 0
        metalness 0
      }
      geometry Box {
        size 0.1 0.1 0.1
      }
    }
  ]
  name "box_9"
  model "box_9"
  boundingObject USE BOX_SHAPE
  physics USE box_phy
  recognitionColors [
    1 0 0
  ]
}
DEF box_10 Solid {
  translation -0.49611 -1.99491 0.0496118
  rotation 1.31509e-16 -1.011e-16 -1 0.301075
  children [
    DEF BOX_SHAPE Shape {
      appearance PBRAppearance {
        baseColor 1 0 0
        metalness 0
      }
      geometry Box {
        size 0.1 0.1 0.1
      }
    }
  ]
  name "box_10"
  model "box_10"
  boundingObject USE BOX_SHAPE
  physics USE box_phy
  recognitionColors [
    1 0 0
  ]
}
DEF box_13 Solid {
  translation 0.940053 -1.98546 0.0496118
  rotation 6.674015496430764e-12 -7.153952117854563e-12 -1 6.045649790603482e-06
  children [
    DEF BOX_SHAPE Shape {
      appearance PBRAppearance {
        baseColor 1 0 0
        metalness 0
      }
      geometry Box {
        size 0.1 0.1 0.1
      }
    }
  ]
  name "box_13"
  model "box_13"
  boundingObject USE BOX_SHAPE
  physics USE box_phy
  recognitionColors [
    1 0 0
  ]
}
DEF box_15 Solid {
  translation 0.230422 -0.960268 0.0496118
  rotation -7.0653187632535564e-12 2.4997134444428403e-12 -1 6.04562516098564e-06
  children [
    DEF BOX_SHAPE Shape {
      appearance PBRAppearance {
        baseColor 0 0 1
        metalness 0
      }
      geometry Box {
        size 0.1 0.1 0.1
      }
    }
  ]
  name "box_15"
  model "box_15"
  boundingObject USE BOX_SHAPE
  physics USE box_phy
  recognitionColors [
    0 0 1
  ]
}
DEF box_16 Solid {
  translation -1.36813 -1.29178 0.0496118
  rotation 2.87908e-16 1.51778e-16 -1 0.28144
  children [
    DEF BOX_SHAPE Shape {
      appearance PBRAppearance {
        baseColor 0 0 1
        metalness 0
      }
      geometry Box {
        size 0.1 0.1 0.1
      }
    }
  ]
  name "box_16"
  model "box_16"
  boundingObject USE BOX_SHAPE
  physics USE box_phy
  recognitionColors [
    0 0 1
  ]
}
DEF box_17 Solid {
  translation -0.121187 -2.14114 0.0496118
  rotation -4.244582478316062e-12 -2.3483933305074236e-12 -1 6.045625161041047e-06
  children [
    DEF BOX_SHAPE Shape {
      appearance PBRAppearance {
        baseColor 0 0 1
        metalness 0
      }
      geometry Box {
        size 0.1 0.1 0.1
      }
    }
  ]
  name "box_17"
  model "box_17"
  boundingObject USE BOX_SHAPE
  physics USE box_phy
  recognitionColors [
    0 0 1
  ]
}
DEF box_18 Solid {
  translation -0.808914 -1.6523 0.0496118
  rotation 4.5925e-16 -1.68846e-16 -1 0.261805
  children [
    DEF BOX_SHAPE Shape {
      appearance PBRAppearance {
        baseColor 0 0 1
        metalness 0
      }
      geometry Box {
        size 0.1 0.1 0.1
      }
    }
  ]
  name "box_18"
  model "box_18"
  boundingObject USE BOX_SHAPE
  physics USE box_phy
  recognitionColors [
    0 0 1
  ]
}
DEF box_19 Solid {
  translation -0.752864 -0.625445 0.0496118
  rotation -8.60488e-17 1.09296e-16 1 0.438508
  children [
    DEF BOX_SHAPE Shape {
      appearance PBRAppearance {
        baseColor 0 0 1
        metalness 0
      }
      geometry Box {
        size 0.1 0.1 0.1
      }
    }
  ]
  name "box_19"
  model "box_19"
  boundingObject USE BOX_SHAPE
  physics USE box_phy
  recognitionColors [
    0 0 1
  ]
}
DEF box_20 Solid {
  translation -0.198456 -1.49317 0.0496118
  rotation 8.26305e-19 8.35453e-17 -1 0.353435
  children [
    DEF BOX_SHAPE Shape {
      appearance PBRAppearance {
        baseColor 0 0 1
        metalness 0
      }
      geometry Box {
        size 0.1 0.1 0.1
      }
    }
  ]
  name "box_20"
  model "box_20"
  boundingObject USE BOX_SHAPE
  physics USE box_phy
  recognitionColors [
    0 0 1
  ]
}
Solid {
  translation 0 -3 0.05
  children [
    DEF shape_muro Shape {
      appearance VarnishedPine {
      }
      geometry Box {
        size 4 0.01 0.1
      }
    }
  ]
  name "muro_sur"
  boundingObject USE shape_muro
}
Solid {
  translation 0 0.66 0.05
  children [
    DEF shape_muro Shape {
      appearance VarnishedPine {
      }
      geometry Box {
        size 2.8 0.01 0.1
      }
    }
  ]
  name "separación"
  boundingObject USE shape_muro
}
Solid {
  translation -2 -1 0.05
  rotation 0 0 1 1.5707903061004251
  children [
    DEF shape_muro Shape {
      appearance VarnishedPine {
      }
      geometry Box {
        size 4 0.01 0.1
      }
    }
  ]
  name "muro_oeste"
  boundingObject USE shape_muro
}
Solid {
  translation 2 -1 0.05
  rotation 0 0 1 1.5707903061004251
  children [
    DEF shape_muro Shape {
      appearance VarnishedPine {
      }
      geometry Box {
        size 4 0.01 0.1
      }
    }
  ]
  name "muro_este"
  boundingObject USE shape_muro
}
DEF zona_A Solid {
  translation -1.7005 0.6625 0.25
  rotation 0 1 0 0
  children [
    DEF señal Shape {
      appearance PBRAppearance {
        baseColor 1 1 0
        metalness 0
      }
      geometry Box {
        size 0.1 0.1 0.1
      }
    }
  ]
  name "zona_A"
  boundingObject USE señal
  recognitionColors [
    1 1 0
  ]
}
DEF zona_B Solid {
  translation 1.7005 0.6625 0.25
  rotation 0 1 0 0
  children [
    DEF señal Shape {
      appearance PBRAppearance {
        baseColor 0 1 1
        metalness 0
      }
      geometry Box {
        size 0.1 0.1 0.1
      }
    }
  ]
  name "zona_B(1)"
  boundingObject USE señal
  recognitionColors [
    0 1 1
  ]
}
DEF store Solid {
  translation 0 2.4525 0.25
  rotation 0 1 0 0
  children [
    DEF señal Shape {
      appearance PBRAppearance {
        baseColor 0.333333 0.333333 0.498039
        metalness 0
      }
      geometry Box {
        size 0.1 0.1 0.1
      }
    }
  ]
  name "store"
  boundingObject USE señal
}
DEF centro Solid {
  translation 0 -1.2 0.3
  rotation -4.1680976249909065e-12 -4.333274753177387e-12 -1 6.045649790545454e-06
  children [
    DEF BOX_SHAPE Shape {
      appearance PBRAppearance {
        baseColor 0 1 0
        metalness 0
      }
      geometry Box {
        size 0.1 0.1 0.1
      }
    }
  ]
  name "centro"
  model "box_1"
  boundingObject USE BOX_SHAPE
  recognitionColors [
    0 1 0
  ]
}
