#VRML_SIM R2023a utf8

EXTERNPROTO "https://raw.githubusercontent.com/cyberbotics/webots/R2023a/projects/objects/backgrounds/protos/TexturedBackground.proto"
EXTERNPROTO "https://raw.githubusercontent.com/cyberbotics/webots/R2023a/projects/objects/backgrounds/protos/TexturedBackgroundLight.proto"
EXTERNPROTO "https://raw.githubusercontent.com/cyberbotics/webots/R2023a/projects/appearances/protos/VarnishedPine.proto"
EXTERNPROTO "https://raw.githubusercontent.com/cyberbotics/webots/R2023a/projects/objects/floors/protos/Floor.proto"

WorldInfo {
}
Viewpoint {
  orientation -0.5832505377832394 0.46722960188145307 0.6644661837153649 2.16330854326952
  position 0.21084998796198384 0.12250790757339668 6.815067639135794
}
TexturedBackground {
}
Floor {
  size 4 4
  tileSize 4 4
  appearance PBRAppearance {
    baseColorMap ImageTexture {
      url [
        "../mapa_1.jpg"
      ]
    }
    metalness 0
  }
}
TexturedBackgroundLight {
}
DEF robot_1 Robot {
  translation 0.297569 -0.00114347 0.0396148
  rotation 5.352689903265187e-05 0.00018242599670316326 0.9999999819278133 -2.336185307179586
  children [
    Solid {
      translation 0.095 0 0.04
      children [
        DEF cuerpo_camara Shape {
          appearance PBRAppearance {
            metalness 0
          }
          geometry Box {
            size 0.01 0.01 0.03
          }
        }
      ]
      name "cuerpo_camara"
      boundingObject USE cuerpo_camara
      physics Physics {
      }
    }
    Camera {
      translation 0.095 0 0.06
      children [
        Shape {
          appearance PBRAppearance {
            baseColor 0 0 0
            metalness 0
          }
          geometry Box {
            size 0.01 0.01 0.01
          }
        }
      ]
      width 1200
      height 1200
      antiAliasing TRUE
      recognition Recognition {
        frameThickness 10
      }
    }
    DistanceSensor {
      translation 0.1 0.02 0
      rotation 0 0 1 0.26180030610042526
      children [
        DEF sensor_shape Shape {
          appearance PBRAppearance {
            baseColor 0 0 1
            metalness 0
          }
          geometry Box {
            size 0.01 0.01 0.01
          }
        }
      ]
      name "ds_left_1"
      boundingObject USE sensor_shape
      physics Physics {
      }
      recognitionColors [
        0 0 0
      ]
      lookupTable [
        0 0 0
        0.3 30 0
      ]
    }
    DistanceSensor {
      translation 0.1 0.04 0
      rotation 0 0 1 0.5235996938995747
      children [
        DEF sensor_shape Shape {
          appearance PBRAppearance {
            baseColor 0 0 1
            metalness 0
          }
          geometry Box {
            size 0.01 0.01 0.01
          }
        }
      ]
      name "ds_left_2"
      boundingObject USE sensor_shape
      physics Physics {
      }
      recognitionColors [
        0 0 0
      ]
      lookupTable [
        0 0 0
        0.3 30 0
      ]
    }
    DistanceSensor {
      translation 0.1 0 0
      children [
        DEF sensor_shape Shape {
          appearance PBRAppearance {
            baseColor 0 0 1
            metalness 0
          }
          geometry Box {
            size 0.01 0.01 0.01
          }
        }
      ]
      name "ds_center"
      boundingObject USE sensor_shape
      physics Physics {
      }
      lookupTable [
        0 0 0
        0.29 30 0
      ]
    }
    DistanceSensor {
      translation 0.1 -0.02 0
      rotation 0 0 1 -0.2617996938995747
      children [
        DEF sensor_shape Shape {
          appearance PBRAppearance {
            baseColor 0 0 1
            metalness 0
          }
          geometry Box {
            size 0.01 0.01 0.01
          }
        }
      ]
      name "ds_right_1"
      boundingObject USE sensor_shape
      physics Physics {
      }
      lookupTable [
        0 0 0
        0.3 30 0
      ]
    }
    DistanceSensor {
      translation 0.1 -0.04 0
      rotation 0 0 1 -0.5235996938995747
      children [
        DEF sensor_shape Shape {
          appearance PBRAppearance {
            baseColor 0 0 1
            metalness 0
          }
          geometry Box {
            size 0.01 0.01 0.01
          }
        }
      ]
      name "ds_right_2"
      boundingObject USE sensor_shape
      physics Physics {
      }
      lookupTable [
        0 0 0
        0.3 30 0
      ]
    }
    HingeJoint {
      jointParameters HingeJointParameters {
        position 17.0207732809251
        axis 0 1 0
        anchor 0.05 0.06 0
      }
      device [
        RotationalMotor {
          name "wheel1"
        }
      ]
      endPoint DEF Wheel1 Solid {
        translation 0.0499998604388116 0.06 2.7344258363222877e-07
        rotation -0.4783333706664932 0.6209646197912162 -0.6209670904922268 4.033918661596566
        children [
          DEF Wheel Shape {
            appearance PBRAppearance {
              baseColor 0 1 0
              metalness 0
            }
            geometry Cylinder {
              height 0.02
              radius 0.04
            }
          }
        ]
        name "solid wheel1"
        boundingObject USE Wheel
        physics DEF Wheel_PH Physics {
        }
      }
    }
    HingeJoint {
      jointParameters HingeJointParameters {
        position 8.734415423406244
        axis 0 1 0
        anchor 0.05 -0.06 0
      }
      device [
        RotationalMotor {
          name "wheel2"
        }
      ]
      endPoint DEF Wheel2 Solid {
        translation 0.049998533052528486 -0.059999999566905826 1.3030387688303816e-06
        rotation 0.24644521748245493 0.6852961375152874 -0.6852984449760949 2.65833382375026
        children [
          USE Wheel
        ]
        name "wheel2"
        boundingObject USE Wheel
        physics USE Wheel_PH
      }
    }
    HingeJoint {
      jointParameters HingeJointParameters {
        position 17.02078430584313
        axis 0 1 0
        anchor -0.05 0.06 0
      }
      device [
        RotationalMotor {
          name "wheel3"
        }
      ]
      endPoint DEF Wheel3 Solid {
        translation -0.04999820278136183 0.05999999956724689 7.867965550065733e-07
        rotation 0.4783374671267055 -0.62096323191948 0.6209653228215907 2.249259503561873
        children [
          USE Wheel
        ]
        name "wheel3"
        boundingObject USE Wheel
        physics USE Wheel_PH
      }
    }
    HingeJoint {
      jointParameters HingeJointParameters {
        position 8.734426201659975
        axis 0 1 0
        anchor -0.05 -0.06 0
      }
      device [
        RotationalMotor {
          name "wheel4"
        }
      ]
      endPoint DEF Wheel4 Solid {
        translation -0.0500014669427183 -0.06000000043275322 1.3030441252047225e-06
        rotation 0.24644129882066124 0.6852968421071951 -0.6852991495934397 2.658341212330911
        children [
          USE Wheel
        ]
        name "wheel4"
        boundingObject USE Wheel
        physics USE Wheel_PH
      }
    }
    DEF BODY Shape {
      appearance PBRAppearance {
        baseColor 1 0 0
        metalness 0
        IBLStrength 0
        normalMapFactor 0
        occlusionMapStrength 0
      }
      geometry Box {
        size 0.2 0.1 0.05
      }
    }
  ]
  name "robot_1"
  boundingObject USE BODY
  physics Physics {
  }
  controller "<none>"
}
DEF robot_2 Robot {
  translation -1.41298 -1.64383 0.039615
  rotation 0.00022633696378536474 -0.0005184379170482817 0.9999998399968398 0.62869
  children [
    Solid {
      translation 0.095 0 0.04
      children [
        DEF cuerpo_camara Shape {
          appearance PBRAppearance {
            metalness 0
          }
          geometry Box {
            size 0.01 0.01 0.03
          }
        }
      ]
      name "cuerpo_camara"
      boundingObject USE cuerpo_camara
      physics Physics {
      }
    }
    Camera {
      translation 0.095 0 0.06
      children [
        Shape {
          appearance PBRAppearance {
            baseColor 0 0 0
            metalness 0
          }
          geometry Box {
            size 0.01 0.01 0.01
          }
        }
      ]
      width 1200
      height 1200
      antiAliasing TRUE
      recognition Recognition {
        frameThickness 10
      }
    }
    DistanceSensor {
      translation 0.1 0.02 0
      rotation 0 0 1 0.26180030610042526
      children [
        DEF sensor_shape Shape {
          appearance PBRAppearance {
            baseColor 0 0 1
            metalness 0
          }
          geometry Box {
            size 0.01 0.01 0.01
          }
        }
      ]
      name "ds_left_1"
      boundingObject USE sensor_shape
      physics Physics {
      }
      recognitionColors [
        0 0 0
      ]
      lookupTable [
        0 0 0
        0.3 30 0
      ]
    }
    DistanceSensor {
      translation 0.1 0.04 0
      rotation 0 0 1 0.5235996938995747
      children [
        DEF sensor_shape Shape {
          appearance PBRAppearance {
            baseColor 0 0 1
            metalness 0
          }
          geometry Box {
            size 0.01 0.01 0.01
          }
        }
      ]
      name "ds_left_2"
      boundingObject USE sensor_shape
      physics Physics {
      }
      recognitionColors [
        0 0 0
      ]
      lookupTable [
        0 0 0
        0.3 30 0
      ]
    }
    DistanceSensor {
      translation 0.1 0 0
      children [
        DEF sensor_shape Shape {
          appearance PBRAppearance {
            baseColor 0 0 1
            metalness 0
          }
          geometry Box {
            size 0.01 0.01 0.01
          }
        }
      ]
      name "ds_center"
      boundingObject USE sensor_shape
      physics Physics {
      }
      lookupTable [
        0 0 0
        0.29 30 0
      ]
    }
    DistanceSensor {
      translation 0.1 -0.02 0
      rotation 0 0 1 -0.2617996938995747
      children [
        DEF sensor_shape Shape {
          appearance PBRAppearance {
            baseColor 0 0 1
            metalness 0
          }
          geometry Box {
            size 0.01 0.01 0.01
          }
        }
      ]
      name "ds_right_1"
      boundingObject USE sensor_shape
      physics Physics {
      }
      lookupTable [
        0 0 0
        0.3 30 0
      ]
    }
    DistanceSensor {
      translation 0.1 -0.04 0
      rotation 0 0 1 -0.5235996938995747
      children [
        DEF sensor_shape Shape {
          appearance PBRAppearance {
            baseColor 0 0 1
            metalness 0
          }
          geometry Box {
            size 0.01 0.01 0.01
          }
        }
      ]
      name "ds_right_2"
      boundingObject USE sensor_shape
      physics Physics {
      }
      lookupTable [
        0 0 0
        0.3 30 0
      ]
    }
    HingeJoint {
      jointParameters HingeJointParameters {
        position 17.0207732809251
        axis 0 1 0
        anchor 0.05 0.06 0
      }
      device [
        RotationalMotor {
          name "wheel1"
        }
      ]
      endPoint DEF Wheel1 Solid {
        translation 0.0499998604388116 0.06 2.7344258363222877e-07
        rotation -0.4783333706664932 0.6209646197912162 -0.6209670904922268 4.033918661596566
        children [
          DEF Wheel Shape {
            appearance PBRAppearance {
              baseColor 0 1 0
              metalness 0
            }
            geometry Cylinder {
              height 0.02
              radius 0.04
            }
          }
        ]
        name "solid wheel1"
        boundingObject USE Wheel
        physics DEF Wheel_PH Physics {
        }
      }
    }
    HingeJoint {
      jointParameters HingeJointParameters {
        position 8.734415423406244
        axis 0 1 0
        anchor 0.05 -0.06 0
      }
      device [
        RotationalMotor {
          name "wheel2"
        }
      ]
      endPoint DEF Wheel2 Solid {
        translation 0.049998533052528486 -0.059999999566905826 1.3030387688303816e-06
        rotation 0.24644521748245493 0.6852961375152874 -0.6852984449760949 2.65833382375026
        children [
          USE Wheel
        ]
        name "wheel2"
        boundingObject USE Wheel
        physics USE Wheel_PH
      }
    }
    HingeJoint {
      jointParameters HingeJointParameters {
        position 17.02078430584313
        axis 0 1 0
        anchor -0.05 0.06 0
      }
      device [
        RotationalMotor {
          name "wheel3"
        }
      ]
      endPoint DEF Wheel3 Solid {
        translation -0.04999820278136183 0.05999999956724689 7.867965550065733e-07
        rotation 0.4783374671267055 -0.62096323191948 0.6209653228215907 2.249259503561873
        children [
          USE Wheel
        ]
        name "wheel3"
        boundingObject USE Wheel
        physics USE Wheel_PH
      }
    }
    HingeJoint {
      jointParameters HingeJointParameters {
        position 8.734426201659975
        axis 0 1 0
        anchor -0.05 -0.06 0
      }
      device [
        RotationalMotor {
          name "wheel4"
        }
      ]
      endPoint DEF Wheel4 Solid {
        translation -0.0500014669427183 -0.06000000043275322 1.3030441252047225e-06
        rotation 0.24644129882066124 0.6852968421071951 -0.6852991495934397 2.658341212330911
        children [
          USE Wheel
        ]
        name "wheel4"
        boundingObject USE Wheel
        physics USE Wheel_PH
      }
    }
    DEF BODY Shape {
      appearance PBRAppearance {
        baseColor 1 0 0
        metalness 0
        IBLStrength 0
        normalMapFactor 0
        occlusionMapStrength 0
      }
      geometry Box {
        size 0.2 0.1 0.05
      }
    }
  ]
  name "robot_2"
  boundingObject USE BODY
  physics Physics {
  }
  controller "<none>"
}
DEF robot_3 Robot {
  translation 1.59436 -1.51651 0.039615
  rotation 0.00018366499629662736 -8.120739836255538e-05 0.9999999798362635 2.1144
  children [
    Solid {
      translation 0.095 0 0.04
      children [
        DEF cuerpo_camara Shape {
          appearance PBRAppearance {
            metalness 0
          }
          geometry Box {
            size 0.01 0.01 0.03
          }
        }
      ]
      name "cuerpo_camara"
      boundingObject USE cuerpo_camara
      physics Physics {
      }
    }
    Camera {
      translation 0.095 0 0.06
      children [
        Shape {
          appearance PBRAppearance {
            baseColor 0 0 0
            metalness 0
          }
          geometry Box {
            size 0.01 0.01 0.01
          }
        }
      ]
      width 1200
      height 1200
      antiAliasing TRUE
      recognition Recognition {
        frameThickness 10
      }
    }
    DistanceSensor {
      translation 0.1 0.02 0
      rotation 0 0 1 0.26180030610042526
      children [
        DEF sensor_shape Shape {
          appearance PBRAppearance {
            baseColor 0 0 1
            metalness 0
          }
          geometry Box {
            size 0.01 0.01 0.01
          }
        }
      ]
      name "ds_left_1"
      boundingObject USE sensor_shape
      physics Physics {
      }
      recognitionColors [
        0 0 0
      ]
      lookupTable [
        0 0 0
        0.3 30 0
      ]
    }
    DistanceSensor {
      translation 0.1 0.04 0
      rotation 0 0 1 0.5235996938995747
      children [
        DEF sensor_shape Shape {
          appearance PBRAppearance {
            baseColor 0 0 1
            metalness 0
          }
          geometry Box {
            size 0.01 0.01 0.01
          }
        }
      ]
      name "ds_left_2"
      boundingObject USE sensor_shape
      physics Physics {
      }
      recognitionColors [
        0 0 0
      ]
      lookupTable [
        0 0 0
        0.3 30 0
      ]
    }
    DistanceSensor {
      translation 0.1 0 0
      children [
        DEF sensor_shape Shape {
          appearance PBRAppearance {
            baseColor 0 0 1
            metalness 0
          }
          geometry Box {
            size 0.01 0.01 0.01
          }
        }
      ]
      name "ds_center"
      boundingObject USE sensor_shape
      physics Physics {
      }
      lookupTable [
        0 0 0
        0.29 30 0
      ]
    }
    DistanceSensor {
      translation 0.1 -0.02 0
      rotation 0 0 1 -0.2617996938995747
      children [
        DEF sensor_shape Shape {
          appearance PBRAppearance {
            baseColor 0 0 1
            metalness 0
          }
          geometry Box {
            size 0.01 0.01 0.01
          }
        }
      ]
      name "ds_right_1"
      boundingObject USE sensor_shape
      physics Physics {
      }
      lookupTable [
        0 0 0
        0.3 30 0
      ]
    }
    DistanceSensor {
      translation 0.1 -0.04 0
      rotation 0 0 1 -0.5235996938995747
      children [
        DEF sensor_shape Shape {
          appearance PBRAppearance {
            baseColor 0 0 1
            metalness 0
          }
          geometry Box {
            size 0.01 0.01 0.01
          }
        }
      ]
      name "ds_right_2"
      boundingObject USE sensor_shape
      physics Physics {
      }
      lookupTable [
        0 0 0
        0.3 30 0
      ]
    }
    HingeJoint {
      jointParameters HingeJointParameters {
        position 17.0207732809251
        axis 0 1 0
        anchor 0.05 0.06 0
      }
      device [
        RotationalMotor {
          name "wheel1"
        }
      ]
      endPoint DEF Wheel1 Solid {
        translation 0.0499998604388116 0.06 2.7344258363222877e-07
        rotation -0.4783333706664932 0.6209646197912162 -0.6209670904922268 4.033918661596566
        children [
          DEF Wheel Shape {
            appearance PBRAppearance {
              baseColor 0 1 0
              metalness 0
            }
            geometry Cylinder {
              height 0.02
              radius 0.04
            }
          }
        ]
        name "solid wheel1"
        boundingObject USE Wheel
        physics DEF Wheel_PH Physics {
        }
      }
    }
    HingeJoint {
      jointParameters HingeJointParameters {
        position 8.734415423406244
        axis 0 1 0
        anchor 0.05 -0.06 0
      }
      device [
        RotationalMotor {
          name "wheel2"
        }
      ]
      endPoint DEF Wheel2 Solid {
        translation 0.049998533052528486 -0.059999999566905826 1.3030387688303816e-06
        rotation 0.24644521748245493 0.6852961375152874 -0.6852984449760949 2.65833382375026
        children [
          USE Wheel
        ]
        name "wheel2"
        boundingObject USE Wheel
        physics USE Wheel_PH
      }
    }
    HingeJoint {
      jointParameters HingeJointParameters {
        position 17.02078430584313
        axis 0 1 0
        anchor -0.05 0.06 0
      }
      device [
        RotationalMotor {
          name "wheel3"
        }
      ]
      endPoint DEF Wheel3 Solid {
        translation -0.04999820278136183 0.05999999956724689 7.867965550065733e-07
        rotation 0.4783374671267055 -0.62096323191948 0.6209653228215907 2.249259503561873
        children [
          USE Wheel
        ]
        name "wheel3"
        boundingObject USE Wheel
        physics USE Wheel_PH
      }
    }
    HingeJoint {
      jointParameters HingeJointParameters {
        position 8.734426201659975
        axis 0 1 0
        anchor -0.05 -0.06 0
      }
      device [
        RotationalMotor {
          name "wheel4"
        }
      ]
      endPoint DEF Wheel4 Solid {
        translation -0.0500014669427183 -0.06000000043275322 1.3030441252047225e-06
        rotation 0.24644129882066124 0.6852968421071951 -0.6852991495934397 2.658341212330911
        children [
          USE Wheel
        ]
        name "wheel4"
        boundingObject USE Wheel
        physics USE Wheel_PH
      }
    }
    DEF BODY Shape {
      appearance PBRAppearance {
        baseColor 1 0 0
        metalness 0
        IBLStrength 0
        normalMapFactor 0
        occlusionMapStrength 0
      }
      geometry Box {
        size 0.2 0.1 0.05
      }
    }
  ]
  name "robot_3"
  boundingObject USE BODY
  physics Physics {
  }
  controller "<none>"
}
DEF robot_4 Robot {
  translation -0.456013 1.18011 0.039615
  rotation 0.0001736889973417499 2.1010499678441558e-05 0.9999999846953456 -3.095405307179586
  children [
    DistanceSensor {
      translation 0.08 0.04 -0.027
      rotation 0 1 0 1.5707996938995747
      children [
        Shape {
          appearance PBRAppearance {
            baseColor 1 0 0
            metalness 0
          }
          geometry Box {
            size 0.005 0.01 0.01
          }
        }
      ]
      name "ir_left"
      type "infra-red"
    }
    DistanceSensor {
      translation 0.08 -0.04 -0.027
      rotation 0 1 0 1.5707996938995747
      children [
        Shape {
          appearance PBRAppearance {
            baseColor 1 0 0
            metalness 0
          }
          geometry Box {
            size 0.005 0.01 0.01
          }
        }
      ]
      name "ir_right"
      type "infra-red"
    }
    DistanceSensor {
      translation 0.1 0.02 0
      rotation 0 0 1 0.26180030610042526
      children [
        DEF sensor_shape Shape {
          appearance PBRAppearance {
            baseColor 0 0 1
            metalness 0
          }
          geometry Box {
            size 0.01 0.01 0.01
          }
        }
      ]
      name "ds_left_1"
      boundingObject USE sensor_shape
      physics Physics {
      }
      recognitionColors [
        0 0 0
      ]
      lookupTable [
        0 0 0
        0.3 30 0
      ]
    }
    DistanceSensor {
      translation 0.1 0.04 0
      rotation 0 0 1 0.5235996938995747
      children [
        DEF sensor_shape Shape {
          appearance PBRAppearance {
            baseColor 0 0 1
            metalness 0
          }
          geometry Box {
            size 0.01 0.01 0.01
          }
        }
      ]
      name "ds_left_2"
      boundingObject USE sensor_shape
      physics Physics {
      }
      recognitionColors [
        0 0 0
      ]
      lookupTable [
        0 0 0
        0.3 30 0
      ]
    }
    DistanceSensor {
      translation 0.1 0 0
      children [
        DEF sensor_shape Shape {
          appearance PBRAppearance {
            baseColor 0 0 1
            metalness 0
          }
          geometry Box {
            size 0.01 0.01 0.01
          }
        }
      ]
      name "ds_center"
      boundingObject USE sensor_shape
      physics Physics {
      }
      lookupTable [
        0 0 0
        0.29 30 0
      ]
    }
    DistanceSensor {
      translation 0.1 -0.02 0
      rotation 0 0 1 -0.2617996938995747
      children [
        DEF sensor_shape Shape {
          appearance PBRAppearance {
            baseColor 0 0 1
            metalness 0
          }
          geometry Box {
            size 0.01 0.01 0.01
          }
        }
      ]
      name "ds_right_1"
      boundingObject USE sensor_shape
      physics Physics {
      }
      lookupTable [
        0 0 0
        0.3 30 0
      ]
    }
    DistanceSensor {
      translation 0.1 -0.04 0
      rotation 0 0 1 -0.5235996938995747
      children [
        DEF sensor_shape Shape {
          appearance PBRAppearance {
            baseColor 0 0 1
            metalness 0
          }
          geometry Box {
            size 0.01 0.01 0.01
          }
        }
      ]
      name "ds_right_2"
      boundingObject USE sensor_shape
      physics Physics {
      }
      lookupTable [
        0 0 0
        0.3 30 0
      ]
    }
    HingeJoint {
      jointParameters HingeJointParameters {
        position 17.0207732809251
        axis 0 1 0
        anchor 0.05 0.06 0
      }
      device [
        RotationalMotor {
          name "wheel1"
        }
      ]
      endPoint DEF Wheel1 Solid {
        translation 0.0499998604388116 0.06 2.7344258363222877e-07
        rotation -0.4783333706664932 0.6209646197912162 -0.6209670904922268 4.033918661596566
        children [
          DEF Wheel Shape {
            appearance PBRAppearance {
              baseColor 0 1 0
              metalness 0
            }
            geometry Cylinder {
              height 0.02
              radius 0.04
            }
          }
        ]
        name "solid wheel1"
        boundingObject USE Wheel
        physics DEF Wheel_PH Physics {
        }
      }
    }
    HingeJoint {
      jointParameters HingeJointParameters {
        position 8.734415423406244
        axis 0 1 0
        anchor 0.05 -0.06 0
      }
      device [
        RotationalMotor {
          name "wheel2"
        }
      ]
      endPoint DEF Wheel2 Solid {
        translation 0.049998533052528486 -0.059999999566905826 1.3030387688303816e-06
        rotation 0.24644521748245493 0.6852961375152874 -0.6852984449760949 2.65833382375026
        children [
          USE Wheel
        ]
        name "wheel2"
        boundingObject USE Wheel
        physics USE Wheel_PH
      }
    }
    HingeJoint {
      jointParameters HingeJointParameters {
        position 17.02078430584313
        axis 0 1 0
        anchor -0.05 0.06 0
      }
      device [
        RotationalMotor {
          name "wheel3"
        }
      ]
      endPoint DEF Wheel3 Solid {
        translation -0.04999820278136183 0.05999999956724689 7.867965550065733e-07
        rotation 0.4783374671267055 -0.62096323191948 0.6209653228215907 2.249259503561873
        children [
          USE Wheel
        ]
        name "wheel3"
        boundingObject USE Wheel
        physics USE Wheel_PH
      }
    }
    HingeJoint {
      jointParameters HingeJointParameters {
        position 8.734426201659975
        axis 0 1 0
        anchor -0.05 -0.06 0
      }
      device [
        RotationalMotor {
          name "wheel4"
        }
      ]
      endPoint DEF Wheel4 Solid {
        translation -0.0500014669427183 -0.06000000043275322 1.3030441252047225e-06
        rotation 0.24644129882066124 0.6852968421071951 -0.6852991495934397 2.658341212330911
        children [
          USE Wheel
        ]
        name "wheel4"
        boundingObject USE Wheel
        physics USE Wheel_PH
      }
    }
    DEF BODY Shape {
      appearance PBRAppearance {
        baseColor 0.333333 0.666667 1
        metalness 0
        IBLStrength 0
        normalMapFactor 0
        occlusionMapStrength 0
      }
      geometry Box {
        size 0.2 0.1 0.05
      }
    }
  ]
  name "robot_4"
  boundingObject USE BODY
  physics Physics {
  }
  controller "searcher"
}
Robot {
  name "supervisor"
  controller "supervisor_lines"
  supervisor TRUE
}
DEF box_1 Solid {
  translation 1.48528 -0.273657 0.04961181229639128
  rotation -4.1680976249909065e-12 -4.333274753177387e-12 -1 6.045649790545454e-06
  children [
    DEF BOX_SHAPE Shape {
      appearance PBRAppearance {
        baseColor 1 0 0
        metalness 0
      }
      geometry Box {
        size 0.1 0.1 0.1
      }
    }
  ]
  name "box_1"
  model "box_1"
  boundingObject USE BOX_SHAPE
  physics Physics {
    density -1
    mass 1
  }
  recognitionColors [
    1 0 0
  ]
}
DEF box_2 Solid {
  translation 0.0822365 0.561314 0.0496118
  rotation 5.627928571461135e-12 2.4997518137144247e-12 -0.9999999999999999 6.045625161073053e-06
  children [
    DEF BOX_SHAPE Shape {
      appearance PBRAppearance {
        baseColor 0 0 1
        metalness 0
      }
      geometry Box {
        size 0.1 0.1 0.1
      }
    }
  ]
  name "box_2"
  model "box_2"
  boundingObject USE BOX_SHAPE
  physics Physics {
    density -1
    mass 1
  }
  recognitionColors [
    0 0 1
  ]
}
DEF box_3 Solid {
  translation 0.107289 -1.72483 0.0496118
  rotation -8.068282582910022e-13 -2.2602353878768024e-12 -1 6.045625161061994e-06
  children [
    DEF BOX_SHAPE Shape {
      appearance PBRAppearance {
        baseColor 0 0 1
        metalness 0
      }
      geometry Box {
        size 0.1 0.1 0.1
      }
    }
  ]
  name "box_3"
  model "box_3"
  boundingObject USE BOX_SHAPE
  physics Physics {
    density -1
    mass 1
  }
  recognitionColors [
    0 0 1
  ]
}
DEF box_4 Solid {
  translation 1.43055 0.147783 0.0496118
  rotation -1.89666e-16 1.70455e-16 -1 0.340345
  children [
    DEF BOX_SHAPE Shape {
      appearance PBRAppearance {
        baseColor 0 0 1
        metalness 0
      }
      geometry Box {
        size 0.1 0.1 0.1
      }
    }
  ]
  name "box_4"
  model "box_4"
  boundingObject USE BOX_SHAPE
  physics Physics {
    density -1
    mass 1
  }
  recognitionColors [
    0 0 1
  ]
}
DEF box_5 Solid {
  translation -1.51108 0.458276 0.0496118
  rotation -1.14869e-16 -1.28563e-16 1 0.287973
  children [
    DEF BOX_SHAPE Shape {
      appearance PBRAppearance {
        baseColor 1 0 0
        metalness 0
      }
      geometry Box {
        size 0.1 0.1 0.1
      }
    }
  ]
  name "box_5"
  model "box_5"
  boundingObject USE BOX_SHAPE
  physics Physics {
    density -1
    mass 1
  }
  recognitionColors [
    1 0 0
  ]
}
DEF box_6 Solid {
  translation 1.5755 0.502425 0.04961181229639128
  rotation -1.192507954931382e-11 5.2747457082485944e-12 -1 6.0456497905797125e-06
  children [
    DEF BOX_SHAPE Shape {
      appearance PBRAppearance {
        baseColor 1 0 0
        metalness 0
      }
      geometry Box {
        size 0.1 0.1 0.1
      }
    }
  ]
  name "box_6"
  model "box_6"
  boundingObject USE BOX_SHAPE
  physics Physics {
    density -1
    mass 1
  }
  recognitionColors [
    1 0 0
  ]
}
DEF box_7 Solid {
  translation 1.44115 1.18835 0.049611812296391264
  rotation -1.34740027621794e-12 -1.0220101886933985e-13 -0.9999999999999999 6.0456497906023715e-06
  children [
    DEF BOX_SHAPE Shape {
      appearance PBRAppearance {
        baseColor 1 0 0
        metalness 0
      }
      geometry Box {
        size 0.1 0.1 0.1
      }
    }
  ]
  name "box_7"
  model "box_7"
  boundingObject USE BOX_SHAPE
  physics Physics {
    density -1
    mass 1
  }
  recognitionColors [
    1 0 0
  ]
}
DEF box_8 Solid {
  translation -0.72516 -0.326812 0.0496118
  rotation -1.7881322385671303e-12 -1.4244102285689888e-12 -1 6.045649790565141e-06
  children [
    DEF BOX_SHAPE Shape {
      appearance PBRAppearance {
        baseColor 1 0 0
        metalness 0
      }
      geometry Box {
        size 0.1 0.1 0.1
      }
    }
  ]
  name "box_8"
  model "box_8"
  boundingObject USE BOX_SHAPE
  physics Physics {
    density -1
    mass 1
  }
  recognitionColors [
    1 0 0
  ]
}
DEF box_9 Solid {
  translation 0.5653664804029314 0.4705938448050859 0.04955397128919615
  rotation -0.013896508657903072 0.9995180783940972 0.02775784592673378 0.0003906899320571952
  children [
    DEF BOX_SHAPE Shape {
      appearance PBRAppearance {
        baseColor 1 0 0
        metalness 0
      }
      geometry Box {
        size 0.1 0.1 0.1
      }
    }
  ]
  name "box_9"
  model "box_9"
  boundingObject USE BOX_SHAPE
  physics Physics {
    density -1
    mass 1
  }
  recognitionColors [
    1 0 0
  ]
}
DEF box_10 Solid {
  translation -1.6045 -1.01232 0.0496118
  rotation 1.31509e-16 -1.011e-16 -1 0.301075
  children [
    DEF BOX_SHAPE Shape {
      appearance PBRAppearance {
        baseColor 1 0 0
        metalness 0
      }
      geometry Box {
        size 0.1 0.1 0.1
      }
    }
  ]
  name "box_10"
  model "box_10"
  boundingObject USE BOX_SHAPE
  physics Physics {
    density -1
    mass 1
  }
  recognitionColors [
    1 0 0
  ]
}
DEF box_11 Solid {
  translation 0.194717 -1.22685 0.0496118
  rotation 1.03222e-18 -8.24858e-17 1 0.248703
  children [
    DEF BOX_SHAPE Shape {
      appearance PBRAppearance {
        baseColor 1 0 0
        metalness 0
      }
      geometry Box {
        size 0.1 0.1 0.1
      }
    }
  ]
  name "box_11"
  model "box_11"
  boundingObject USE BOX_SHAPE
  physics Physics {
    density -1
    mass 1
  }
  recognitionColors [
    1 0 0
  ]
}
DEF box_12 Solid {
  translation -0.593056 -1.65075 0.0496118
  rotation -1.4128753749514014e-11 3.423648018513516e-12 -1 6.045649790575208e-06
  children [
    DEF BOX_SHAPE Shape {
      appearance PBRAppearance {
        baseColor 1 0 0
        metalness 0
      }
      geometry Box {
        size 0.1 0.1 0.1
      }
    }
  ]
  name "box_12"
  model "box_12"
  boundingObject USE BOX_SHAPE
  physics Physics {
    density -1
    mass 1
  }
  recognitionColors [
    1 0 0
  ]
}
DEF box_13 Solid {
  translation 1.01746 -1.41398 0.0496118
  rotation 6.674015496430764e-12 -7.153952117854563e-12 -1 6.045649790603482e-06
  children [
    DEF BOX_SHAPE Shape {
      appearance PBRAppearance {
        baseColor 1 0 0
        metalness 0
      }
      geometry Box {
        size 0.1 0.1 0.1
      }
    }
  ]
  name "box_13"
  model "box_13"
  boundingObject USE BOX_SHAPE
  physics Physics {
    density -1
    mass 1
  }
  recognitionColors [
    1 0 0
  ]
}
DEF box_14 Solid {
  translation 0.785928 -0.738745 0.049611812296391285
  rotation 1.6280199624008152e-13 -4.640216332166844e-12 -1 6.045625161016845e-06
  children [
    DEF BOX_SHAPE Shape {
      appearance PBRAppearance {
        baseColor 0 0 1
        metalness 0
      }
      geometry Box {
        size 0.1 0.1 0.1
      }
    }
  ]
  name "box_14"
  model "box_14"
  boundingObject USE BOX_SHAPE
  physics Physics {
    density -1
    mass 1
  }
  recognitionColors [
    0 0 1
  ]
}
DEF box_15 Solid {
  translation -0.566697 0.616129 0.049611812296391285
  rotation -7.0653187632535564e-12 2.4997134444428403e-12 -1 6.04562516098564e-06
  children [
    DEF BOX_SHAPE Shape {
      appearance PBRAppearance {
        baseColor 0 0 1
        metalness 0
      }
      geometry Box {
        size 0.1 0.1 0.1
      }
    }
  ]
  name "box_15"
  model "box_15"
  boundingObject USE BOX_SHAPE
  physics Physics {
    density -1
    mass 1
  }
  recognitionColors [
    0 0 1
  ]
}
DEF box_16 Solid {
  translation -0.452296 -1.03297 0.0496118
  rotation 2.87908e-16 1.51778e-16 -1 0.28144
  children [
    DEF BOX_SHAPE Shape {
      appearance PBRAppearance {
        baseColor 0 0 1
        metalness 0
      }
      geometry Box {
        size 0.1 0.1 0.1
      }
    }
  ]
  name "box_16"
  model "box_16"
  boundingObject USE BOX_SHAPE
  physics Physics {
    density -1
    mass 1
  }
  recognitionColors [
    0 0 1
  ]
}
DEF box_17 Solid {
  translation -1.05529 -0.96353 0.04961181229639129
  rotation -4.244582478316062e-12 -2.3483933305074236e-12 -1 6.045625161041047e-06
  children [
    DEF BOX_SHAPE Shape {
      appearance PBRAppearance {
        baseColor 0 0 1
        metalness 0
      }
      geometry Box {
        size 0.1 0.1 0.1
      }
    }
  ]
  name "box_17"
  model "box_17"
  boundingObject USE BOX_SHAPE
  physics Physics {
    density -1
    mass 1
  }
  recognitionColors [
    0 0 1
  ]
}
DEF box_18 Solid {
  translation -0.442672 0.0854048 0.0496118
  rotation 4.5925e-16 -1.68846e-16 -1 0.261805
  children [
    DEF BOX_SHAPE Shape {
      appearance PBRAppearance {
        baseColor 0 0 1
        metalness 0
      }
      geometry Box {
        size 0.1 0.1 0.1
      }
    }
  ]
  name "box_18"
  model "box_18"
  boundingObject USE BOX_SHAPE
  physics Physics {
    density -1
    mass 1
  }
  recognitionColors [
    0 0 1
  ]
}
DEF box_19 Solid {
  translation 0.140164 -0.619756 0.0496118
  rotation -8.60488e-17 1.09296e-16 1 0.438508
  children [
    DEF BOX_SHAPE Shape {
      appearance PBRAppearance {
        baseColor 0 0 1
        metalness 0
      }
      geometry Box {
        size 0.1 0.1 0.1
      }
    }
  ]
  name "box_19"
  model "box_19"
  boundingObject USE BOX_SHAPE
  physics Physics {
    density -1
    mass 1
  }
  recognitionColors [
    0 0 1
  ]
}
DEF box_20 Solid {
  translation 0.653517 -0.242692 0.0496118
  rotation 8.26305e-19 8.35453e-17 -1 0.353435
  children [
    DEF BOX_SHAPE Shape {
      appearance PBRAppearance {
        baseColor 0 0 1
        metalness 0
      }
      geometry Box {
        size 0.1 0.1 0.1
      }
    }
  ]
  name "box_20"
  model "box_20"
  boundingObject USE BOX_SHAPE
  physics Physics {
    density -1
    mass 1
  }
  recognitionColors [
    0 0 1
  ]
}
Solid {
  translation 0 -2 0.05
  children [
    DEF shape_muro Shape {
      appearance VarnishedPine {
      }
      geometry Box {
        size 4 0.01 0.1
      }
    }
  ]
  name "muro_sur"
  boundingObject USE shape_muro
}
Solid {
  translation -2 0 0.05
  rotation 0 0 1 1.5707903061004251
  children [
    DEF shape_muro Shape {
      appearance VarnishedPine {
      }
      geometry Box {
        size 4 0.01 0.1
      }
    }
  ]
  name "muro_oeste"
  boundingObject USE shape_muro
}
Solid {
  translation 2 0 0.05
  rotation 0 0 1 1.5707903061004251
  children [
    DEF shape_muro Shape {
      appearance VarnishedPine {
      }
      geometry Box {
        size 4 0.01 0.1
      }
    }
  ]
  name "muro_este"
  boundingObject USE shape_muro
}
DEF zona_A Solid {
  translation -1.68934 1.16217 0.25
  children [
    DEF señal Shape {
      appearance PBRAppearance {
        baseColor 1 1 0
        metalness 0
      }
      geometry Box {
        size 0.1 0.1 0.1
      }
    }
  ]
  name "zona_A"
  boundingObject USE señal
  recognitionColors [
    1 1 0
  ]
}
